Workbook

Sheet 建设规模表-硬件
A1: 序号 | B1: 区域 | C1: 设备类型 | D1: 设备名称 | E1: 数量 （全量） | F1: 单位 | G1: 型号 | H1: 厂商 | I1: 参数配置 | J1: 设备物理尺寸
A2: 一、崇左城南二楼机房
A3: 1 | B3: 管理区 | C3: 交换机 | D3: 核心交换机 | E3: 2 | F3: 台 | G3: CE16804 | H3: 华为 | I3: 高度：9.8U 电源：3*3000WAC 端口：1块36*40G+1块48*10G 交换容量：387Tbps/1161Tbps 包转发率：115200Mpps | J3: 10U
A4: 2 | B4: 管理区 | C4: 交换机 | D4: 管理区万兆管理交换机 | E4: 4 | F4: 台 | G4: CE6881H-48S6CQ | H4: 华为 | I4: 高度：1U 电源：1+1AC 端口：48×10GE 光口＋6×40GE 光口，支持堆叠,支持IPv6；满配多模光模块 交换容量：4.8Tbps/96Tbps 包转发率：2000Mpps | J4: 1U
A5: 3 | B5: 管理区 | C5: 交换机 | D5: 运维区万兆交换机 | E5: 2 | F5: 台 | G5: CE6881H-48S6CQ | H5: 华为 | I5: 高度：1U 电源：1+1AC 端口：48×10GE 光口＋6×40GE 光口，支持堆叠,支持IPv6；满配多模光模块 交换容量：4.8Tbps/96Tbps 包转发率：2000Mpps | J5: 1U
A6: 4 | B6: 管理区 | C6: 安全设备 | D6: 管理防火墙 | E6: 2 | F6: 台 | G6: Eudemon1000E-F125 | H6: 华为 | I6: 高度：1U 电源：1+1 AC 端口：2*40GE/100GE QSFP28 + 2*40GE QSFP+ + 8*25GE/10GE*ZSFP+ + 20*10GE SFP+,本期配置10个10G多模模块 容量：120G | J6: 1U
A7: 5 | B7: 管理区 | C7: 安全设备 | D7: 网闸 | E7: 2 | F7: 台 | G7: TopRules(FT-A10) | H7: 天融信 | I7: 2U，飞腾，统信V20，内外端机各16GB内存，内外端机各1TB机械硬盘+16G Msata,内外分别1个HA口、1个管理口、4个千兆电口和4个千兆光口（默认带4个千兆多模光模块），4个万兆光口（默认带4个万兆多模光模块）,冗余电源,文件传输速率（一对万兆接口）：6493.310Mbps；文件传输延时：0.449ms；网络层交换速率（1对口）：9869.94Mbps，网络延时：0.102ms | J7: 2U
A8: 6 | B8: 管理区 | C8: 安全设备 | D8: SSL VPN网关 | E8: 2 | F8: 台 | G8: G1300 | H8: 三未信安（华为） | I8: 默认网口情况：6个RJ-45千兆自适应电口，4个SPF万兆光口，4个SPF+万兆光口，北京其阳华夏科技有限公司 系统版本：统信UOS：Server：V20：1060e 主板：CB-1727A： CPU：海光3250：海光信息技术股份有限公司 内存：2*8G：SCC08GU03H3F1C-32AAG：西安紫光国芯半导体股份有限公司 存储：2*960G：MSSE001TXA0S4E100：湖北长江万润半导体技术有限公司 电源：冗余电源350W： 密码模块：SJK1727：V2.0 | J8: 2U
A9: 7 | B9: 管理区 | C9: 安全设备 | D9: 态势感知服务器 | E9: 4 | F9: 台 | G9: R5930 G2 | H9: 中兴 | I9: CPU：2*海光 7360(24 Cores,2.2GHz) 内存：256GB(8*32GB) 系统盘：2*480GB 2.5"SATA SSD支持热插拨 缓存盘：2×3.2TB PCle NVMe U.2盘，随机写 5 年 3DWPD,按 NUMA 平衡 配置 阵列卡： 1 块独立RAID卡，2G Cache,端口数≥14,端口速率：12Gb/s,配置电 池或者电容；支持 RAID0、1、10、50、60 以及直通 数据盘：6*16T 网卡：1×x双口GbE网卡；2×双口10GbE网卡（配4个多模光模块，支持虚 拟机多队列技术、SRIOV 和 DPDK，按 NUMA 平衡配置），带ilo管理口， 支持IPv6 系统管理：服务器标准远程卡 电源：双电源，几余配置 | J9: 2U
A10: 8 | B10: 政务外网区 | C10: 服务器 | D10: 网络节点 | E10: 2 | F10: 台 | G10: R220K V2 | H10: 烽火 | I10: 2颗KunPeng920-5250 CPU型号（48核心，2.6GHz主频），512GB内存（16根32G）,2个480GB SATA SSD硬盘，4个千兆电口，3个双口10Gb类型局域网卡（含光模块），1块4GB缓存Raid，2块220V交流和220V高压直流自适应电源模块（铂金级，额定功耗900W，含配套电源线 | J10: 2U
A11: 9 | B11: 政务外网区 | C11: 服务器 | D11: 高性能网络节点 | E11: 2 | F11: 台 | G11: R220K V2 | H11: 烽火 | I11: 2颗KunPeng920-5250 CPU型号（48核心，2.6GHz主频），256GB内存（8根32G）,2个480GB SATA SSD硬盘，4个千兆电口，4个双口10Gb类型局域网卡（含光模块），1块4GB缓存Raid，2块220V交流和220V高压直流自适应电源模块（铂金级，额定功耗900W，含配套电源线 | J11: 2U
A12: 10 | B12: 政务外网区 | C12: 服务器 | D12: 计算节点 | E12: 5 | F12: 台 | G12: R220K V2 | H12: 烽火 | I12: 2颗KunPeng920-7260 CPU型号（64核心，2.6GHz主频），1024GB内存（32根32G）,2个480GB SATA SSD硬盘，4个千兆电口，3个双口10Gb类型局域网卡（含光模块），1块4GB缓存Raid，2块220V交流和220V高压直流自适应电源模块（铂金级，额定功耗900W，含配套电源线 | J12: 2U
A13: 11 | B13: 政务外网区 | C13: 服务器 | D13: 计算节点(超分比1) | E13: 4 | F13: 台 | G13: R220K V2 | H13: 烽火 | I13: 2颗KunPeng920-7260 CPU型号（64核心，2.6GHz主频），1024GB内存（32根32G）,2个480GB SATA SSD硬盘，4个千兆电口，3个双口10Gb类型局域网卡（含光模块），1块4GB缓存Raid，2块220V交流和220V高压直流自适应电源模块（铂金级，额定功耗900W，含配套电源线 | J13: 2U
A14: 12 | B14: 政务外网区 | C14: 服务器 | D14: BMGW节点 | E14: 2 | F14: 台 | G14: R220K V2 | H14: 烽火 | I14: 2颗KunPeng920-5250 CPU型号（48核心，2.6GHz主频），256GB内存（8根32G）,2个480GB SATA SSD硬盘，4个千兆电口，4个双口10Gb类型局域网卡（含光模块），1块4GB缓存Raid，2块220V交流和220V高压直流自适应电源模块（铂金级，额定功耗900W，含配套电源线 | J14: 2U
... A40: 38 | B40: 政务外网区 | C40: 安全设备 | D40: 流量探针 | E40: 2 | F40: 台 | G40: UTSNX3-HHB | H40: 绿盟 | I40: CPU：Hygon5380（16C，2.5GHz） 系统：银河麒麟V10,内核5.4 内存：64G 硬盘存储：32T（8T*4） 网卡：4电口4千兆口*1；4万兆光口*1，配4个千兆多模模块，2个万兆多模模块 电源：交流双电源；输入电压范围：100-240V ；输入电流：8A；额定功率：550W | J40: 2U
A41: 70 | B41: 政务外网区 | C41: 服务器 | D41: X86计算节点（利旧） | E41: 4 | F41: 台 | G41: 2288 | H41: 华为 | I41: CPU: 2* Intel Xeon Gold 6348 (28 Cores,2.6 GHz） 内存：768GB（24*32G） 系统盘：2* 480G SATA SSD 阵列卡：1块独立RAID卡,2G Cache,端口数≥8,端口速率:12Gb/s,配置电池或者电容,支持RAID0、1、10、50、60以及直通 网卡： 1×双口GbE网卡 3×双口25GbE网卡(配6个10G多模光模块,NUMA平衡) 带ilo管理口 支持IPv6 系统管理：服务器标准远程卡 电源：双电源，冗余配置 | J41: 2U
A42: 39 | B42: 互联网区 | C42: 服务器 | D42: 网络节点 | E42: 2 | F42: 台 | G42: R220K V2 | H42: 烽火 | I42: 2颗KunPeng920-5250 CPU型号（48核心，2.6GHz主频），512GB内存（16根32G）,2个480GB SATA SSD硬盘，4个千兆电口，3个双口10Gb类型局域网卡（含光模块），1块4GB缓存Raid，2块220V交流和220V高压直流自适应电源模块（铂金级，额定功耗900W，含配套电源线 | J42: 2U
A43: 40 | B43: 互联网区 | C43: 服务器 | D43: 高性能网络节点 | E43: 2 | F43: 台 | G43: R220K V2 | H43: 烽火 | I43: 2颗KunPeng920-5250 CPU型号（48核心，2.6GHz主频），256GB内存（8根32G）,2个480GB SATA SSD硬盘，4个千兆电口，4个双口10Gb类型局域网卡（含光模块），1块4GB缓存Raid，2块220V交流和220V高压直流自适应电源模块（铂金级，额定功耗900W，含配套电源线 | J43: 2U
A44: 41 | B44: 互联网区 | C44: 服务器 | D44: 计算节点 | E44: 4 | F44: 台 | G44: R220K V2 | H44: 烽火 | I44: 2颗KunPeng920-7260 CPU型号（64核心，2.6GHz主频），1024GB内存（32根32G）,2个480GB SATA SSD硬盘，4个千兆电口，3个双口10Gb类型局域网卡（含光模块），1块4GB缓存Raid，2块220V交流和220V高压直流自适应电源模块（铂金级，额定功耗900W，含配套电源线 | J44: 2U
A45: 42 | B45: 互联网区 | C45: 服务器 | D45: 计算节点(超分比1) | E45: 4 | F45: 台 | G45: R220K V2 | H45: 烽火 | I45: 2颗KunPeng920-7260 CPU型号（64核心，2.6GHz主频），1024GB内存（32根32G）,2个480GB SATA SSD硬盘，4个千兆电口，3个双口10Gb类型局域网卡（含光模块），1块4GB缓存Raid，2块220V交流和220V高压直流自适应电源模块（铂金级，额定功耗900W，含配套电源线 | J45: 2U
A46: 43 | B46: 互联网区 | C46: 服务器 | D46: 安全服务节点 | E46: 2 | F46: 台 | G46: R220K V2 | H46: 烽火 | I46: 2颗KunPeng920-5250 CPU型号（48核心，2.6GHz主频），512GB内存（16根32G）,2个480GB SATA SSD硬盘，4个千兆电口，4个双口10Gb类型局域网卡（含光模块），1块4GB缓存Raid，2块220V交流和220V高压直流自适应电源模块（铂金级，额定功耗900W，含配套电源线 | J46: 2U
A47: 44 | B47: 互联网区 | C47: 服务器 | D47: 管理节点 | E47: 10 | F47: 台 | G47: R220K V2 | H47: 烽火 | I47: 2颗KunPeng920-5250 CPU型号（48核心，2.6GHz主频），768GB内存（24根32G）,2个960GB SATA SSD硬盘，5个8TB SATA HDD硬盘，1个3.2TB NVMe SSD硬盘，4个千兆电口，2个双口10Gb类型局域网卡（含光模块），1块4GB缓存Raid，2块220V交流和220V高压直流自适应电源模块（铂金级，额定功耗900W，含配套电源线 | J47: 2U
A48: 45 | B48: 互联网区 | C48: 服务器 | D48: 对象存储节点 | E48: 3 | F48: 台 | G48: R220K V2 | H48: 烽火 | I48: 2颗KunPeng920-5220 CPU型号（32核心，2.6GHz主频），256GB内存（8根32G）,2个960GB SATA SSD硬盘，12个8TB SATA HDD硬盘，2个3.2TB NVMe SSD硬盘，4个千兆电口，2个双口10Gb类型局域网卡（含光模块），1块4GB缓存Raid，2块220V交流和220V高压直流自适应电源模块（铂金级，额定功耗900W，含配套电源线 | J48: 2U
A49: 46 | B49: 互联网区 | C49: 服务器 | D49: 租户安全节点 | E49: 5 | F49: 台 | G49: R5930 G2 | H49: 中兴 | I49: CPU：2*海光 7380(32 Cores,2.0GHz) 内存：1024GB (32*32G) 系统盘：2*480GB 2.5°SATA SSD支持热插 阵列卡：1 块独立RAID卡，2G Cache,端口数≥8,端口速率：12Gb/s,配置电池 或者电容；支持 RAID0、1、10、50、60 以及直通 数据盘：6*16T 网卡：1x双口GbE网卡；2x双口10GbE网卡（配 4个多模光模块，支持 虚拟机多队列技术、SRIOV 和 DPDK，按 NUMA 平衡配置），带ilo管理 口， 支持IPv6 系统管理：服务器标准远程卡 电源：双电源，几余配置 | J49: 2U
A50: 47 | B50: 互联网区 | C50: 服务器 | D50: 租户安全管理节点 | E50: 2 | F50: 台 | G50: R5930 G2 | H50: 中兴 | I50: CPU：2*海光 7360(24 Cores,2.2GHz) 内存：256GB(8*32GB) 系统盘：2*480GB 2.5"SATA SSD 支持热插拔 阵列卡：1 块独立RAID卡，2G Cache,端口数≥8,端口速率：12Gb/s,配置电池 或者电容；支持 RAID0、1、10、50、60 以及直通 数据盘：3*16T 网卡：1x双口GbE网卡；2x双口10GbE网卡（配 4个多模光模块，支持 虚拟机多队列技术、SRIOV 和 DPDK，按 NUMA 平衡配置），带ilo管理 口， 支持IPv6 系统管理：服务器标准远程卡 电源：双电源，几余配置 | J50: 2U
A51: 48 | B51: 互联网区 | C51: 服务器 | D51: 本地备份节点 | E51: 1 | F51: 台 | G51: 中兴R5530 | H51: 中兴 | I51: CPU: 2*海光CPU≥(48 Cores,2.6GHz) 内存：256GB(8*32GB) 系统盘:2×960GB 2.5" SATA SSD 缓存盘：4×3.2TB NVMe SSD卡,随机写5年3DWPD,按NUMA平衡配置 数据盘：36×20TB 3.5" 7.2k SATA,热插拔 阵列卡：1 块独立RAID卡,4G Cache,端口数≥8,端口速率:12Gb/s,配置电池或者电容;支持 RAID0、1、10、 50、60 以及直通 网卡：'1×双口GbE网卡，3×双口10GbE网卡(SFP+,配6个多模光模块,支持虚拟机多队列技术、SRIOV和DPDK,中断队列数大于10) 电源：双电源，冗余配置 | J51: 4U
A52: 49 | B52: 互联网区 | C52: 存储 | D52: 块存储服务-混闪分布式存储(SATA) | E52: 1 | F52: 套 | G52: OceanStor Pacific 9520 | H52: 华为 | I52: OceanStor Pacific 9520(2U EXP,12*3.5",2*32C 2.6GHz,4*GE,K22R-02)*4 通用内存-DDR4 RDIMM-16GB-288pin-0.68ns-2933000KHz-1.2V-ECC-1Rank(2G*4bit),prememtest-crc-load*24 HP380 以太网卡-25GE光口-双端口-SFP28(不含光模块)-半高半长-全高拉手条-PCIe 3.0 x8*8 8TB 7.2K RPM SATA硬盘单元(3.5")*44 480GB SSD SATA硬盘单元(2.5")*8 3.2TB SSD NVMe硬盘单元(2.5")*4 SAS/SATA RAID 16口标卡,RAID0,1,5,6,10,50,60,2GB Cache,支持超级电容和边带管理（垫片专用）*4 高速电缆-内部高速Slimline-2*mini SAS HD-0.85m&0.75m-(Slimline X8 直头)-(2*((31AWG*1Pair+31AWG*2Drain)*8+31AWG*1Pair*4))-(2*Internal mini SAS HD 弯头)-1分2 Slimline-2*mini SAS HD*8 块存储高级版软件-SATA/NL SAS盘,可得容量每TiB*204 块存储高级版软件-SATA/NL SAS盘,可得容量每TiB-3年订阅与保障年费*204 | J52: 2U
A53: 50 | B53: 互联网区 | C53: 存储 | D53: 块存储服务-混闪分布式存储(SSD) | E53: 1 | F53: 套 | G53: OceanStor Dorado 5500 V6 | H53: 华为 | I53: OceanStor Dorado 5500 V6(2U,双控,SAS,交流\240V高压直流,384GB 缓存,4*(4*12Gb) SAS,25*2.5英寸,SPE53C0225)*1 4端口 SmartIO I/O模块(SFP+,10Gb ETH)*4 3.84TB SSD SAS硬盘单元(2.5")*16 光跳线-DLC/PC-DLC/PC-多模-3m-A1a.2-2mm-42mm DLC-OM3弯曲不敏感*16 高级包许可(含DeviceManager,Thin,Migration,Snap,Replication,Clone,QoS,Erase,DME IQ,UltraPath,Virtualization,Metro,CDP)*1 | J53: 2U
... A73: 69 | B73: 互联网区 | C73: 安全设备 | D73: 流量探针 | E73: 2 | F73: 台 | G73: TopAPT3000 | H73: 天融信 | I73: 2U,海光3250(2.8GHZ,8核)*1,国产操作系统,内存32G(2*16G),机械硬盘4TB,mSATA卡128G,6个千兆电口(含HA和管理口),4个千兆光口插槽,冗余电源,3个扩展槽位, | J73: 2U
A74: 70 | B74: 互联网区 | C74: 服务器 | D74: X86计算节点（利旧） | E74: 6 | F74: 台 | G74: 2288 | H74: 华为 | I74: CPU: 2* Intel Xeon Gold 6348 (28 Cores,2.6 GHz） 内存：768GB（24*32G） 系统盘：2* 480G SATA SSD 阵列卡：1块独立RAID卡,2G Cache,端口数≥8,端口速率:12Gb/s,配置电池或者电容,支持RAID0、1、10、50、60以及直通 网卡： 1×双口GbE网卡 3×双口25GbE网卡(配6个10G多模光模块,NUMA平衡) 带ilo管理口 支持IPv6 系统管理：服务器标准远程卡 电源：双电源，冗余配置 | J74: 2U
A75: 柳东机房东202机房
A76: 1 | B76: 异地备份中心 | C76: 服务器 | D76: 异地备份节点 | E76: 2 | F76: 台 | G76: R5530 G2 | H76: 中兴 | I76: CPU: 2*海光7280(32 Cores,2.0GHz) 内存：256GB(32GB×8) 系统盘:2×480GB 2.5" SATA SSD,热插拔 缓存盘：4×3.2TB NVMe SSD卡,随机写5年3DWPD,按NUMA平衡配置 数据盘：36×18TB 3.5" 7.2k SATA,热插拔 阵列卡：1块SAS直通卡,端口速率12Gb/s,可管理所有硬盘，系统盘支持硬raid0,1且数据盘做直通 网卡：'1×双口GbE网卡，2×双口10GbE网卡(SFP+,配4个多模光模块,支持虚拟机多队列技术、SRIOV和DPDK,中断队列数大于10) 电源：双电源，冗余配置 | J76: 4U
A77: 2 | B77: 异地备份中心 | C77: 安全设备 | D77: 备份中心防火墙 | E77: 2 | F77: 台 | G77: Eudemon1000E-F55 | H77: 华为 | I77: 高度：1U 电源：1+1 AC 端口：8*GE COMBO + 4*GE RJ45 + 10*10GE SFP+，本期配置8个10G多模模块 容量：40G | J77: 1U

Sheet 组网拓扑

Sheet 机房平面
A1: 一、主要建设机房： | B1: 崇左城南二楼机房
A2: 机房名： | B2: 崇左城南二楼机房
A3: 占用机架数量： | B3: 本期新增设备占用20架
A27: 三、异地备份中心： | B27: 柳州市柳州电信云计算数据中心
A28: 机房名： | B28: 2楼东202IDC机房
A29: 占用机架数量： | B29: 本期新增设备占用2架

Sheet 机架立面图
A1: 崇左市城南枢纽楼二层IDC机房
C2: HW105-01机架 | H2: HW105-02机架 | L2: HW105-03机架 | P2: HW105-04机架 | T2: HW105-05机架 | X2: HW105-06机架 | AB2: HW105-07机架 | AF2: HW105-08机架 | AJ2: HW105-09机架
B3: 42U | G3: 42U | K3: 42U | L3: 空调 | O3: 42U | S3: 42U | W3: 42U | AA3: 42U | AB3: 空调 | AE3: 42U | AI3: 42U
B4: 41U | C4: 政务外网区出口防火墙-华为1000E-F55 | D4: 1 | E4: 180 | G4: 41U | H4: 政务外网区出口防火墙-华为1000E-F55 | I4: 2 | J4: 180 | K4: 41U | O4: 41U | P4: 政务外网区万兆管理交换机-华为CE6881H | Q4: 1 | R4: 349 | S4: 41U | T4: 政务外网区万兆管理交换机-华为CE6881H | U4: 2 | V4: 349 | W4: 41U | X4: 政务外网区万兆业务交换机-华为CE6881H | Y4: 1 | Z4: 349 | AA4: 41U | AE4: 41U | AF4: 政务外网区万兆业务交换机-华为CE6881H | AG4: 2 | AH4: 349 | AI4: 41U
B5: 40U | G5: 40U | K5: 40U | O5: 40U | S5: 40U | W5: 40U | AA5: 40U | AE5: 40U | AI5: 40U
B6: 39U | C6: 政务外网区安全交换机-华为CE6881H | D6: 1 | E6: 349 | G6: 39U | H6: 政务外网区安全交换机-华为CE6881H | I6: 2 | J6: 349 | K6: 39U | O6: 39U | P6: 政务外网区万兆专线交换机-华为CE6881H | Q6: 1 | R6: 349 | S6: 39U | T6: 政务外网区万兆专线交换机-华为CE6881H | U6: 2 | V6: 349 | W6: 39U | X6: 政务外网区万兆业务管理交换机-华为CE6881H | Y6: 1 | Z6: 349 | AA6: 39U | AE6: 39U | AF6: 政务外网区万兆业务管理交换机-华为CE6881H | AG6: 2 | AH6: 349 | AI6: 39U
B7: 38U | G7: 38U | K7: 38U | O7: 38U | S7: 38U | W7: 38U | AA7: 38U | AE7: 38U | AI7: 38U
B8: 37U | C8: 政务外网区安全池交换机-华为CE6881H | D8: 1 | E8: 349 | G8: 37U | H8: 政务外网区安全池交换机-华为CE6881H | I8: 2 | J8: 349 | K8: 37U | O8: 37U | S8: 37U | W8: 37U | AA8: 37U | AE8: 37U | AF8: 政务外网区千兆BMC交换机-华为5855 | AG8: 2 | AH8: 65 | AI8: 37U
B9: 36U | G9: 36U | K9: 36U | O9: 36U | S9: 36U | W9: 36U | AA9: 36U | AE9: 36U | AI9: 36U
B10: 35U | G10: 35U | H10: 政务外网区千兆BMC交换机-华为5855 | I10: 1 | J10: 65 | K10: 35U | O10: 35U | S10: 35U | W10: 35U | AA10: 35U | AE10: 35U | AI10: 35U
B11: 34U | G11: 34U | K11: 34U | O11: 34U | S11: 34U | W11: 34U | AA11: 34U | AE11: 34U | AI11: 34U
B12: 33U | G12: 33U | K12: 33U | O12: 33U | S12: 33U | W12: 33U | AA12: 33U | AE12: 33U | AI12: 33U
B13: 32U | G13: 32U | K13: 32U | O13: 32U | S13: 32U | W13: 32U | AA13: 32U | AE13: 32U | AI13: 32U
B14: 31U | G14: 31U | K14: 31U | O14: 31U | S14: 31U | W14: 31U | AA14: 31U | AE14: 31U | AI14: 31U
B15: 30U | G15: 30U | K15: 30U | O15: 30U | S15: 30U | W15: 30U | AA15: 30U | AE15: 30U | AI15: 30U
B16: 29U | G16: 29U | K16: 29U | O16: 29U | S16: 29U | W16: 29U | AA16: 29U | AE16: 29U | AI16: 29U
B17: 28U | G17: 28U | K17: 28U | O17: 28U | S17: 28U | W17: 28U | AA17: 28U | AE17: 28U | AI17: 28U
B18: 27U | G18: 27U | K18: 27U | O18: 27U | S18: 27U | W18: 27U | AA18: 27U | AE18: 27U | AI18: 27U
B19: 26U | G19: 26U | K19: 26U | O19: 26U | S19: 26U | W19: 26U | AA19: 26U | AE19: 26U | AI19: 26U
B20: 25U | G20: 25U | K20: 25U | O20: 25U | S20: 25U | W20: 25U | AA20: 25U | AE20: 25U | AI20: 25U
B21: 24U | G21: 24U | K21: 24U | O21: 24U | S21: 24U | W21: 24U | AA21: 24U | AE21: 24U | AI21: 24U
B22: 23U | G22: 23U | K22: 23U | O22: 23U | S22: 23U | W22: 23U | AA22: 23U | AE22: 23U | AI22: 23U
B23: 22U | G23: 22U | K23: 22U | O23: 22U | S23: 22U | W23: 22U | AA23: 22U | AE23: 22U | AI23: 22U
B24: 21U | G24: 21U | K24: 21U | O24: 21U | S24: 21U | W24: 21U | X24: 政务外网区增强型网络节点-烽火R220K V2 | Y24: 1 | Z24: 450 | AA24: 21U | AE24: 21U | AI24: 21U
B25: 20U | G25: 20U | K25: 20U | O25: 20U | P25: 政务外网区堡垒机-信安SecHAC | Q25: 1 | R25: 285 | S25: 20U | T25: 政务外网区时间戳服务器-信安SecSign-TS | U25: 1 | V25: 280 | W25: 20U | AA25: 20U | AE25: 20U | AI25: 20U
B26: 19U | G26: 19U | K26: 19U | O26: 19U | S26: 19U | W26: 19U | AA26: 19U | AE26: 19U | AI26: 19U
B27: 18U | C27: 政务外网区安全节点-烽火R220K V2 | D27: 1 | E27: 450 | G27: 18U | K27: 18U | O27: 18U | S27: 18U | W27: 18U | X27: 政务外网区网络节点-烽火R220K V2 | Y27: 1 | Z27: 450 | AA27: 18U | AE27: 18U | AF27: 政务外网区增强型网络节点-烽火R220K V2 | AG27: 1 | AH27: 450 | AI27: 18U
B28: 17U | G28: 17U | K28: 17U | O28: 17U | P28: 政务外网区综合安全网关-信安SecGW | Q28: 1 | R28: 140 | S28: 17U | T28: 政务外网区堡垒机-信安SecHAC | U28: 2 | V28: 285 | W28: 17U | AA28: 17U | AE28: 17U | AI28: 17U
B29: 16U | G29: 16U | K29: 16U | O29: 16U | S29: 16U | W29: 16U | AA29: 16U | AE29: 16U | AI29: 16U
B30: 15U | C30: 政务外网区流量探针-绿盟UTSNX3-HHB | D30: 1 | E30: 197 | G30: 15U | H30: 政务外网区安全节点-烽火R220K V2 | I30: 2 | J30: 450 | K30: 15U | O30: 15U | P30: 政务外网区签名验签服务器-信安SecHSM-Sign | Q30: 1 | R30: 270 | S30: 15U | W30: 15U | X30: 政务外网区计算节点-烽火R220K V2 | Y30: 9 | Z30: 450 | AA30: 15U | AE30: 15U | AF30: 政务外网区网络节点-烽火R220K V2 | AG30: 2 | AH30: 450 | AI30: 15U
B31: 14U | G31: 14U | K31: 14U | O31: 14U | S31: 14U | T31: 政务外网区综合安全网关-信安SecGW | U31: 2 | V31: 140 | W31: 14U | AA31: 14U | AE31: 14U | AI31: 14U
B32: 13U | G32: 13U | K32: 13U | O32: 13U | S32: 13U | W32: 13U | AA32: 13U | AE32: 13U | AI32: 13U
B33: 12U | C33: 政务外网区租户安全管理-中兴R5930 G2 | D33: 5 | E33: 531 | G33: 12U | H33: 政务外网区流量探针-绿盟UTSNX3-HHB | I33: 2 | J33: 197 | K33: 12U | O33: 12U | P33: 政务外网区服务器密码机-信安SecHSM-Net | Q33: 1 | R33: 270 | S33: 12U | T33: 政务外网区签名验签服务器-信安SecHSM-Sign | U33: 2 | V33: 270 | W33: 12U | X33: 政务外网区计算节点-烽火R220K V2 | Y33: 7 | Z33: 450 | AA33: 12U | AE33: 12U | AF33: 政务外网区计算节点-烽火R220K V2 | AG33: 8 | AH33: 450 | AI33: 12U | AJ33: 政务外网区X86计算节点-华为2255 | AK33: 4 | AL33: 450
B34: 11U | G34: 11U | K34: 11U | O34: 11U | S34: 11U | W34: 11U | AA34: 11U | AE34: 11U | AI34: 11U
B35: 10U | G35: 10U | K35: 10U | O35: 10U | S35: 10U | W35: 10U | AA35: 10U | AE35: 10U | AI35: 10U
B36: 9U | C36: 政务外网区租户安全-中兴R5930 G2 | D36: 3 | E36: 513 | G36: 9U | H36: 政务外网区租户安全管理-中兴R5930 G2 | I36: 4 | J36: 531 | K36: 9U | O36: 9U | P36: 政务外网区管理节点-烽火R220K V2 | Q36: 5 | R36: 521 | S36: 9U | T36: 政务外网区服务器密码机-信安SecHSM-Net | U36: 2 | V36: 270 | W36: 9U | X36: 政务外网区计算节点-烽火R220K V2 | Y36: 5 | Z36: 450 | AA36: 9U | AE36: 9U | AF36: 政务外网区计算节点-烽火R220K V2 | AG36: 6 | AH36: 450 | AI36: 9U | AJ36: 政务外网区X86计算节点-华为2255 | AK36: 3 | AL36: 450
B37: 8U | G37: 8U | K37: 8U | O37: 8U | S37: 8U | W37: 8U | AA37: 8U | AE37: 8U | AI37: 8U
B38: 7U | G38: 7U | K38: 7U | O38: 7U | S38: 7U | W38: 7U | AA38: 7U | AE38: 7U | AI38: 7U
B39: 6U | C39: 政务外网区租户安全-中兴R5930 G2 | D39: 1 | E39: 431 | G39: 6U | H39: 政务外网区租户安全-中兴R5930 G2 | I39: 2 | J39: 431 | K39: 6U | O39: 6U | P39: 政务外网区管理节点-烽火R220K V2 | Q39: 3 | R39: 521 | S39: 6U | T39: 政务外网区管理节点-烽火R220K V2 | U39: 4 | V39: 521 | W39: 6U | X39: 政务外网区计算节点-烽火R220K V2 | Y39: 3 | Z39: 450 | AA39: 6U | AE39: 6U | AF39: 政务外网区计算节点-烽火R220K V2 | AG39: 4 | AH39: 450 | AI39: 6U | AJ39: 政务外网区X86计算节点-华为2255 | AK39: 2 | AL39: 450
B40: 5U | G40: 5U | K40: 5U | O40: 5U | S40: 5U | W40: 5U | AA40: 5U | AE40: 5U | AI40: 5U
...

Sheet 设备功耗表
A1: 序号 | B1: 区域 | C1: 机柜号 | D1: 设备名 | E1: 设备型号 | F1: 单位 | G1: 数量 | H1: 单台功耗 （W） | I1: 功耗小计 （W） | J1: 机柜 总功耗 | K1: 单台高度 （U） | L1: 供电类型 | M1: 引电需求 | N1: 备注
A2: 一、崇左城南二楼机房
A3: 1 | B3: 政务外网区 | C3: HW105-01 | D3: 政务外网区出口防火墙-1 | E3: 华为1000E-F55 | F3: 台 | G3: 1 | H3: 180 | I3: =H3*G3 -> 180 | J3: =SUM(I3:I11) -> 4018 | K3: 1 | L3: 220V交流 | M3: 2路10A引电
A4: 2 | D4: 政务外网区安全交换机-1 | E4: 华为CE6881H | F4: 台 | G4: 1 | H4: 349 | I4: =H4*G4 -> 349 | K4: 1 | L4: 220V交流 | M4: 2路10A引电
A5: 3 | D5: 政务外网区安全池交换机-1 | E5: 华为CE6881H | F5: 台 | G5: 1 | H5: 349 | I5: =H5*G5 -> 349 | K5: 1 | L5: 220V交流 | M5: 2路10A引电
A6: 4 | D6: 政务外网区安全节点-1 | E6: 烽火R220K V2 | F6: 台 | G6: 1 | H6: 450 | I6: =H6*G6 -> 450 | K6: 2 | L6: 220V交流 | M6: 2路10A引电
A7: 5 | D7: 政务外网区流量探针-1 | E7: 绿盟UTSNX3-HHB | F7: 台 | G7: 1 | H7: 197 | I7: =H7*G7 -> 197 | K7: 2 | L7: 220V交流 | M7: 2路10A引电
A8: 6 | D8: 政务外网区租户安全-5 | E8: 中兴R5930 G2 | F8: 台 | G8: 1 | H8: 531 | I8: =H8*G8 -> 531 | K8: 2 | L8: 220V交流 | M8: 2路10A引电
A9: 7 | D9: 政务外网区租户安全-3 | E9: 中兴R5930 G2 | F9: 台 | G9: 1 | H9: 513 | I9: =H9*G9 -> 513 | K9: 2 | L9: 220V交流 | M9: 2路10A引电
A10: 8 | D10: 政务外网区租户安全-1 | E10: 中兴R5930 G2 | F10: 台 | G10: 1 | H10: 431 | I10: =H10*G10 -> 431 | K10: 2 | L10: 220V交流 | M10: 2路10A引电
A11: 9 | D11: 政务外网区核心交换机-1 | E11: 华为CE8865-4C | F11: 台 | G11: 1 | H11: 1018 | I11: =H11*G11 -> 1018 | K11: 2 | L11: 220V交流 | M11: 2路10A引电
A12: 10 | C12: HW105-02 | D12: 政务外网区出口防火墙-2 | E12: 华为1000E-F55 | F12: 台 | G12: 1 | H12: 180 | I12: =H12*G12 -> 180 | J12: =SUM(I12:I20) -> 3570 | K12: 1 | L12: 220V交流 | M12: 2路10A引电
A13: 11 | D13: 政务外网区安全交换机-2 | E13: 华为CE6881H | F13: 台 | G13: 1 | H13: 349 | I13: =H13*G13 -> 349 | K13: 1 | L13: 220V交流 | M13: 2路10A引电
A14: 12 | D14: 政务外网区安全池交换机-2 | E14: 华为CE6881H | F14: 台 | G14: 1 | H14: 349 | I14: =H14*G14 -> 349 | K14: 1 | L14: 220V交流 | M14: 2路10A引电
A15: 13 | D15: 政务外网区千兆BMC交换机-1 | E15: 华为5855 | F15: 台 | G15: 1 | H15: 65 | I15: =H15*G15 -> 65 | K15: 1 | L15: 220V交流 | M15: 2路10A引电
A16: 14 | D16: 政务外网区安全节点-2 | E16: 烽火R220K V2 | F16: 台 | G16: 1 | H16: 450 | I16: =H16*G16 -> 450 | K16: 2 | L16: 220V交流 | M16: 2路10A引电
A17: 15 | D17: 政务外网区流量探针-2 | E17: 绿盟UTSNX3-HHB | F17: 台 | G17: 1 | H17: 197 | I17: =H17*G17 -> 197 | K17: 2 | L17: 220V交流 | M17: 2路10A引电
A18: 16 | D18: 政务外网区租户安全-4 | E18: 中兴R5930 G2 | F18: 台 | G18: 1 | H18: 531 | I18: =H18*G18 -> 531 | K18: 2 | L18: 220V交流 | M18: 2路10A引电
A19: 17 | D19: 政务外网区租户安全-2 | E19: 中兴R5930 G2 | F19: 台 | G19: 1 | H19: 431 | I19: =H19*G19 -> 431 | K19: 2 | L19: 220V交流 | M19: 2路10A引电
A20: 18 | D20: 政务外网区核心交换机-2 | E20: 华为CE8865-4C | F20: 台 | G20: 1 | H20: 1018 | I20: =H20*G20 -> 1018 | K20: 2 | L20: 220V交流 | M20: 2路10A引电
A21: 19 | C21: HW105-04 | D21: 政务外网区万兆管理交换机-1 | E21: 华为CE6881H | F21: 台 | G21: 1 | H21: 349 | I21: =H21*G21 -> 349 | J21: =SUM(I21:I29) -> 3226 | K21: 1 | L21: 220V交流 | M21: 2路10A引电
A22: 20 | C22: HW105-04 | D22: 政务外网区万兆专线交换机-1 | E22: 华为CE6881H | F22: 台 | G22: 1 | H22: 349 | I22: =H22*G22 -> 349 | J22: =SUM(I22:I30) -> 3226 | K22: 1 | L22: 220V交流 | M22: 2路10A引电
A23: 21 | D23: 政务外网区堡垒机-1 | E23: 信安SecHAC | F23: 台 | G23: 1 | H23: 285 | I23: =H23*G23 -> 285 | K23: 2 | L23: 220V交流 | M23: 2路10A引电
A24: 22 | D24: 政务外网区综合安全网关-1 | E24: 信安SecGW | F24: 台 | G24: 1 | H24: 140 | I24: =H24*G24 -> 140 | K24: 1 | L24: 220V交流 | M24: 2路10A引电
A25: 23 | D25: 政务外网区签名验签服务器-1 | E25: 信安SecHSM-Sign | F25: 台 | G25: 1 | H25: 270 | I25: =H25*G25 -> 270 | K25: 2 | L25: 220V交流 | M25: 2路10A引电
A26: 24 | D26: 政务外网区服务器密码机-1 | E26: 信安SecHSM-Net | F26: 台 | G26: 1 | H26: 270 | I26: =H26*G26 -> 270 | K26: 2 | L26: 220V交流 | M26: 2路10A引电
A27: 25 | D27: 政务外网区管理节点-5 | E27: 烽火R220K V2 | F27: 台 | G27: 1 | H27: 521 | I27: =H27*G27 -> 521 | K27: 2 | L27: 220V交流 | M27: 2路10A引电
A28: 26 | D28: 政务外网区管理节点-3 | E28: 烽火R220K V2 | F28: 台 | G28: 1 | H28: 521 | I28: =H28*G28 -> 521 | K28: 2 | L28: 220V交流 | M28: 2路10A引电
A29: 27 | D29: 政务外网区管理节点-1 | E29: 烽火R220K V2 | F29: 台 | G29: 1 | H29: 521 | I29: =H29*G29 -> 521 | K29: 2 | L29: 220V交流 | M29: 2路10A引电
A30: 28 | C30: HW105-05 | D30: 政务外网区万兆管理交换机-2 | E30: 华为CE6881H | F30: 台 | G30: 1 | H30: 349 | I30: =H30*G30 -> 349 | J30: =SUM(I30:I38) -> 2985 | K30: 1 | L30: 220V交流 | M30: 2路10A引电
A31: 29 | C31: HW105-05 | D31: 政务外网区万兆专线交换机-2 | E31: 华为CE6881H | F31: 台 | G31: 1 | H31: 349 | I31: =H31*G31 -> 349 | J31: =SUM(I31:I39) -> 2985 | K31: 1 | L31: 220V交流 | M31: 2路10A引电
A32: 30 | D32: 政务外网区时间戳服务器-1 | E32: 信安SecSign-TS | F32: 台 | G32: 1 | H32: 280 | I32: =H32*G32 -> 280 | K32: 2 | L32: 220V交流 | M32: 2路10A引电
A33: 31 | D33: 政务外网区堡垒机-2 | E33: 信安SecHAC | F33: 台 | G33: 1 | H33: 285 | I33: =H33*G33 -> 285 | K33: 2 | L33: 220V交流 | M33: 2路10A引电
A34: 32 | D34: 政务外网区综合安全网关-2 | E34: 信安SecGW | F34: 台 | G34: 1 | H34: 140 | I34: =H34*G34 -> 140 | K34: 1 | L34: 220V交流 | M34: 2路10A引电
A35: 33 | D35: 政务外网区签名验签服务器-2 | E35: 信安SecHSM-Sign | F35: 台 | G35: 1 | H35: 270 | I35: =H35*G35 -> 270 | K35: 2 | L35: 220V交流 | M35: 2路10A引电
A36: 34 | D36: 政务外网区服务器密码机-2 | E36: 信安SecHSM-Net | F36: 台 | G36: 1 | H36: 270 | I36: =H36*G36 -> 270 | K36: 2 | L36: 220V交流 | M36: 2路10A引电
A37: 35 | D37: 政务外网区管理节点-4 | E37: 烽火R220K V2 | F37: 台 | G37: 1 | H37: 521 | I37: =H37*G37 -> 521 | K37: 2 | L37: 220V交流 | M37: 2路10A引电
A38: 36 | D38: 政务外网区管理节点-2 | E38: 烽火R220K V2 | F38: 台 | G38: 1 | H38: 521 | I38: =H38*G38 -> 521 | K38: 2 | L38: 220V交流 | M38: 2路10A引电
A39: 37 | C39: HW105-06 | D39: 政务外网区万兆业务交换机-1 | E39: 华为CE6881H | F39: 台 | G39: 1 | H39: 349 | I39: =H39*G39 -> 349 | J39: =SUM(I39:I47) -> 3848 | K39: 1 | L39: 220V交流 | M39: 2路10A引电
A40: 38 | D40: 政务外网区万兆业务管理交换机-1 | E40: 华为CE6881H | F40: 台 | G40: 1 | H40: 349 | I40: =H40*G40 -> 349 | K40: 1 | L40: 220V交流 | M40: 2路10A引电
...

Sheet 布线计划表
A1: 机房 | B1: 序号 | C1: 布线起点 | F1: 布线终点 | I1: 电缆名称 | J1: 电缆程式 | K1: 数量 （条） | L1: 长度（米） | M1: 合计 （米） | N1: 敷设方式 | O1: 提供方 | P1: 备注
C2: 机架编号 | D2: 设备名 | E2: 设备型号 | F2: 机架编号 | G2: 设备名 | H2: 设备型号
A3: 崇左城南二楼IDC机房 | B3: 1 | C3: =VLOOKUP(D3,'00设备表'!$D:$F,3,0) -> HW105-01 | D3: 政务外网区出口防火墙-1 | E3: =VLOOKUP(D3,'00设备表'!$D:$F,2,0) -> 华为1000E-F55 | F3: =VLOOKUP(G3,'00设备表'!$D:$F,3,0) -> HW105-02 | G3: 政务外网区出口防火墙-2 | H3: =VLOOKUP(G3,'00设备表'!$D:$F,2,0) -> 华为1000E-F55 | I3: 以太网线 | J3: =IF(I3="多模双头尾纤","LC-LC"&" "&L3&"米",IF(I3="单模双头尾纤","SC-LC"&" "&L3&"米",IF(I3="MPO双头尾纤","MPO-MPO"&" "&L3&"米",IF(I3="以太网线","超五类线",0)))) -> 超五类线 | K3: 2 | L3: =IF(C3=F3,10,(10+ROUNDUP(ABS(MID(C3,7,3)-MID(F3,7,3))/4,0)*5)) -> 15 | M3: =K3*L3 -> 30 | N3: =IF(L3=10,"架内走线","上走线") -> 上走线 | Q3: =IF(ABS(MID(C3,3,3)-MID(F3,3,3))<>0,"建议手动计算",IF(C3=F3,10,(10+ROUNDUP(ABS(MID(C3,7,3)-MID(F3,7,3))/4,0)*5))) -> 15
A4: 崇左城南二楼IDC机房 | B4: 2 | C4: =VLOOKUP(D4,'00设备表'!$D:$F,3,0) -> HW105-01 | D4: 政务外网区出口防火墙-1 | E4: =VLOOKUP(D4,'00设备表'!$D:$F,2,0) -> 华为1000E-F55 | F4: =VLOOKUP(G4,'00设备表'!$D:$F,3,0) -> HW105-01 | G4: 政务外网区核心交换机-1 | H4: =VLOOKUP(G4,'00设备表'!$D:$F,2,0) -> 华为CE8865-4C | I4: 多模双头尾纤 | J4: =IF(I4="多模双头尾纤","LC-LC"&" "&L4&"米",IF(I4="单模双头尾纤","SC-LC"&" "&L4&"米",IF(I4="MPO双头尾纤","MPO-MPO"&" "&L4&"米",IF(I4="以太网线","超五类线",0)))) -> LC-LC 10米 | K4: 2 | L4: =IF(C4=F4,10,(10+ROUNDUP(ABS(MID(C4,7,3)-MID(F4,7,3))/4,0)*5)) -> 10 | N4: =IF(L4=10,"架内走线","上走线") -> 架内走线 | Q4: =IF(ABS(MID(C4,3,3)-MID(F4,3,3))<>0,"建议手动计算",IF(C4=F4,10,(10+ROUNDUP(ABS(MID(C4,7,3)-MID(F4,7,3))/4,0)*5))) -> 10
A5: 崇左城南二楼IDC机房 | B5: 3 | C5: =VLOOKUP(D5,'00设备表'!$D:$F,3,0) -> HW105-01 | D5: 政务外网区出口防火墙-1 | E5: =VLOOKUP(D5,'00设备表'!$D:$F,2,0) -> 华为1000E-F55 | F5: =VLOOKUP(G5,'00设备表'!$D:$F,3,0) -> HW105-02 | G5: 政务外网区核心交换机-2 | H5: =VLOOKUP(G5,'00设备表'!$D:$F,2,0) -> 华为CE8865-4C | I5: 多模双头尾纤 | J5: =IF(I5="多模双头尾纤","LC-LC"&" "&L5&"米",IF(I5="单模双头尾纤","SC-LC"&" "&L5&"米",IF(I5="MPO双头尾纤","MPO-MPO"&" "&L5&"米",IF(I5="以太网线","超五类线",0)))) -> LC-LC 15米 | K5: 2 | L5: =IF(C5=F5,10,(10+ROUNDUP(ABS(MID(C5,7,3)-MID(F5,7,3))/4,0)*5)) -> 15 | N5: =IF(L5=10,"架内走线","上走线") -> 上走线 | P5: 至多云汇聚路由器 | Q5: =IF(ABS(MID(C5,3,3)-MID(F5,3,3))<>0,"建议手动计算",IF(C5=F5,10,(10+ROUNDUP(ABS(MID(C5,7,3)-MID(F5,7,3))/4,0)*5))) -> 15
A6: 崇左城南二楼IDC机房 | B6: 5 | C6: =VLOOKUP(D6,'00设备表'!$D:$F,3,0) -> HW105-01 | D6: 政务外网区出口防火墙-1 | E6: =VLOOKUP(D6,'00设备表'!$D:$F,2,0) -> 华为1000E-F55 | F6: HW104-07 | G6: 政务外网区核心交换机-1 | H6: 华为7706 | I6: 多模双头尾纤 | J6: =IF(I6="多模双头尾纤","LC-LC"&" "&L6&"米",IF(I6="单模双头尾纤","SC-LC"&" "&L6&"米",IF(I6="MPO双头尾纤","MPO-MPO"&" "&L6&"米",IF(I6="以太网线","超五类线",0)))) -> LC-LC 20米 | K6: 2 | L6: =IF(C6=F6,10,(10+ROUNDUP(ABS(MID(C6,7,3)-MID(F6,7,3))/4,0)*5)) -> 20 | N6: =IF(L6=10,"架内走线","上走线") -> 上走线 | P6: 至多云汇聚路由器 | Q6: =IF(ABS(MID(C6,3,3)-MID(F6,3,3))<>0,"建议手动计算",IF(C6=F6,10,(10+ROUNDUP(ABS(MID(C6,7,3)-MID(F6,7,3))/4,0)*5))) -> 建议手动计算
A7: 崇左城南二楼IDC机房 | B7: 6 | C7: =VLOOKUP(D7,'00设备表'!$D:$F,3,0) -> HW105-01 | D7: 政务外网区出口防火墙-1 | E7: =VLOOKUP(D7,'00设备表'!$D:$F,2,0) -> 华为1000E-F55 | F7: =VLOOKUP(G7,'00设备表'!$D:$F,3,0) -> HW105-04 | G7: 政务外网区专线交换机-1 | H7: =VLOOKUP(G7,'00设备表'!$D:$F,2,0) -> 华为CE6881H | I7: 多模双头尾纤 | J7: =IF(I7="多模双头尾纤","LC-LC"&" "&L7&"米",IF(I7="单模双头尾纤","SC-LC"&" "&L7&"米",IF(I7="MPO双头尾纤","MPO-MPO"&" "&L7&"米",IF(I7="以太网线","超五类线",0)))) -> LC-LC 15米 | K7: 2 | L7: =IF(C7=F7,10,(10+ROUNDUP(ABS(MID(C7,7,3)-MID(F7,7,3))/4,0)*5)) -> 15 | N7: =IF(L7=10,"架内走线","上走线") -> 上走线 | Q7: =IF(ABS(MID(C7,3,3)-MID(F7,3,3))<>0,"建议手动计算",IF(C7=F7,10,(10+ROUNDUP(ABS(MID(C7,7,3)-MID(F7,7,3))/4,0)*5))) -> 15
A8: 崇左城南二楼IDC机房 | B8: 7 | C8: =VLOOKUP(D8,'00设备表'!$D:$F,3,0) -> HW105-01 | D8: 政务外网区出口防火墙-1 | E8: =VLOOKUP(D8,'00设备表'!$D:$F,2,0) -> 华为1000E-F55 | F8: =VLOOKUP(G8,'00设备表'!$D:$F,3,0) -> HW105-05 | G8: 政务外网区专线交换机-2 | H8: =VLOOKUP(G8,'00设备表'!$D:$F,2,0) -> 华为CE6881H | I8: 多模双头尾纤 | J8: =IF(I8="多模双头尾纤","LC-LC"&" "&L8&"米",IF(I8="单模双头尾纤","SC-LC"&" "&L8&"米",IF(I8="MPO双头尾纤","MPO-MPO"&" "&L8&"米",IF(I8="以太网线","超五类线",0)))) -> LC-LC 15米 | K8: 2 | L8: =IF(C8=F8,10,(10+ROUNDUP(ABS(MID(C8,7,3)-MID(F8,7,3))/4,0)*5)) -> 15 | N8: =IF(L8=10,"架内走线","上走线") -> 上走线 | Q8: =IF(ABS(MID(C8,3,3)-MID(F8,3,3))<>0,"建议手动计算",IF(C8=F8,10,(10+ROUNDUP(ABS(MID(C8,7,3)-MID(F8,7,3))/4,0)*5))) -> 15
A9: 崇左城南二楼IDC机房 | B9: 9 | C9: =VLOOKUP(D9,'00设备表'!$D:$F,3,0) -> HW105-01 | D9: 政务外网区出口防火墙-1 | E9: =VLOOKUP(D9,'00设备表'!$D:$F,2,0) -> 华为1000E-F55 | F9: =VLOOKUP(G9,'00设备表'!$D:$F,3,0) -> HW109-01 | G9: ODF（柳东方向） | H9: =VLOOKUP(G9,'00设备表'!$D:$F,2,0) -> ODF | I9: 单模双头尾纤 | J9: SC-LC 35米 | K9: 2 | L9: 35 | N9: =IF(L9=10,"架内走线","上走线") -> 上走线 | Q9: =IF(ABS(MID(C9,3,3)-MID(F9,3,3))<>0,"建议手动计算",IF(C9=F9,10,(10+ROUNDUP(ABS(MID(C9,7,3)-MID(F9,7,3))/4,0)*5))) -> 建议手动计算
A10: 崇左城南二楼IDC机房 | B10: 10 | C10: =VLOOKUP(D10,'00设备表'!$D:$F,3,0) -> HW105-01 | D10: 政务外网区出口防火墙-1 | E10: =VLOOKUP(D10,'00设备表'!$D:$F,2,0) -> 华为1000E-F55 | F10: =VLOOKUP(G10,'00设备表'!$D:$F,3,0) -> HW108-07 | G10: 管理区核心交换机-1 | H10: =VLOOKUP(G10,'00设备表'!$D:$F,2,0) -> 华为CE16804 | I10: 多模双头尾纤 | J10: =IF(I10="多模双头尾纤","LC-LC"&" "&L10&"米",IF(I10="单模双头尾纤","SC-LC"&" "&L10&"米",IF(I10="MPO双头尾纤","MPO-MPO"&" "&L10&"米",IF(I10="以太网线","超五类线",0)))) -> LC-LC 20米 | K10: 2 | L10: =IF(C10=F10,10,(10+ROUNDUP(ABS(MID(C10,7,3)-MID(F10,7,3))/4,0)*5)) -> 20 | N10: =IF(L10=10,"架内走线","上走线") -> 上走线 | Q10: =IF(ABS(MID(C10,3,3)-MID(F10,3,3))<>0,"建议手动计算",IF(C10=F10,10,(10+ROUNDUP(ABS(MID(C10,7,3)-MID(F10,7,3))/4,0)*5))) -> 建议手动计算
A11: 崇左城南二楼IDC机房 | B11: 11 | C11: =VLOOKUP(D11,'00设备表'!$D:$F,3,0) -> HW105-02 | D11: 政务外网区出口防火墙-2 | E11: =VLOOKUP(D11,'00设备表'!$D:$F,2,0) -> 华为1000E-F55 | F11: =VLOOKUP(G11,'00设备表'!$D:$F,3,0) -> HW105-01 | G11: 政务外网区核心交换机-1 | H11: =VLOOKUP(G11,'00设备表'!$D:$F,2,0) -> 华为CE8865-4C | I11: 多模双头尾纤 | J11: =IF(I11="多模双头尾纤","LC-LC"&" "&L11&"米",IF(I11="单模双头尾纤","SC-LC"&" "&L11&"米",IF(I11="MPO双头尾纤","MPO-MPO"&" "&L11&"米",IF(I11="以太网线","超五类线",0)))) -> LC-LC 15米 | K11: 2 | L11: =IF(C11=F11,10,(10+ROUNDUP(ABS(MID(C11,7,3)-MID(F11,7,3))/4,0)*5)) -> 15 | N11: =IF(L11=10,"架内走线","上走线") -> 上走线 | Q11: =IF(ABS(MID(C11,3,3)-MID(F11,3,3))<>0,"建议手动计算",IF(C11=F11,10,(10+ROUNDUP(ABS(MID(C11,7,3)-MID(F11,7,3))/4,0)*5))) -> 15
A12: 崇左城南二楼IDC机房 | B12: 12 | C12: =VLOOKUP(D12,'00设备表'!$D:$F,3,0) -> HW105-02 | D12: 政务外网区出口防火墙-2 | E12: =VLOOKUP(D12,'00设备表'!$D:$F,2,0) -> 华为1000E-F55 | F12: =VLOOKUP(G12,'00设备表'!$D:$F,3,0) -> HW105-02 | G12: 政务外网区核心交换机-2 | H12: =VLOOKUP(G12,'00设备表'!$D:$F,2,0) -> 华为CE8865-4C | I12: 多模双头尾纤 | J12: =IF(I12="多模双头尾纤","LC-LC"&" "&L12&"米",IF(I12="单模双头尾纤","SC-LC"&" "&L12&"米",IF(I12="MPO双头尾纤","MPO-MPO"&" "&L12&"米",IF(I12="以太网线","超五类线",0)))) -> LC-LC 10米 | K12: 2 | L12: =IF(C12=F12,10,(10+ROUNDUP(ABS(MID(C12,7,3)-MID(F12,7,3))/4,0)*5)) -> 10 | N12: =IF(L12=10,"架内走线","上走线") -> 架内走线 | Q12: =IF(ABS(MID(C12,3,3)-MID(F12,3,3))<>0,"建议手动计算",IF(C12=F12,10,(10+ROUNDUP(ABS(MID(C12,7,3)-MID(F12,7,3))/4,0)*5))) -> 10
A13: 崇左城南二楼IDC机房 | B13: 14 | C13: =VLOOKUP(D13,'00设备表'!$D:$F,3,0) -> HW105-02 | D13: 政务外网区出口防火墙-2 | E13: =VLOOKUP(D13,'00设备表'!$D:$F,2,0) -> 华为1000E-F55 | F13: HW104-06 | G13: 政务外网区核心交换机-2 | H13: 华为7706 | I13: 多模双头尾纤 | J13: =IF(I13="多模双头尾纤","LC-LC"&" "&L13&"米",IF(I13="单模双头尾纤","SC-LC"&" "&L13&"米",IF(I13="MPO双头尾纤","MPO-MPO"&" "&L13&"米",IF(I13="以太网线","超五类线",0)))) -> LC-LC 15米 | K13: 2 | L13: =IF(C13=F13,10,(10+ROUNDUP(ABS(MID(C13,7,3)-MID(F13,7,3))/4,0)*5)) -> 15 | N13: =IF(L13=10,"架内走线","上走线") -> 上走线 | Q13: =IF(ABS(MID(C13,3,3)-MID(F13,3,3))<>0,"建议手动计算",IF(C13=F13,10,(10+ROUNDUP(ABS(MID(C13,7,3)-MID(F13,7,3))/4,0)*5))) -> 建议手动计算
A14: 崇左城南二楼IDC机房 | B14: 15 | C14: =VLOOKUP(D14,'00设备表'!$D:$F,3,0) -> HW105-02 | D14: 政务外网区出口防火墙-2 | E14: =VLOOKUP(D14,'00设备表'!$D:$F,2,0) -> 华为1000E-F55 | F14: =VLOOKUP(G14,'00设备表'!$D:$F,3,0) -> HW105-04 | G14: 政务外网区专线交换机-1 | H14: =VLOOKUP(G14,'00设备表'!$D:$F,2,0) -> 华为CE6881H | I14: 多模双头尾纤 | J14: =IF(I14="多模双头尾纤","LC-LC"&" "&L14&"米",IF(I14="单模双头尾纤","SC-LC"&" "&L14&"米",IF(I14="MPO双头尾纤","MPO-MPO"&" "&L14&"米",IF(I14="以太网线","超五类线",0)))) -> LC-LC 15米 | K14: 2 | L14: =IF(C14=F14,10,(10+ROUNDUP(ABS(MID(C14,7,3)-MID(F14,7,3))/4,0)*5)) -> 15 | N14: =IF(L14=10,"架内走线","上走线") -> 上走线 | Q14: =IF(ABS(MID(C14,3,3)-MID(F14,3,3))<>0,"建议手动计算",IF(C14=F14,10,(10+ROUNDUP(ABS(MID(C14,7,3)-MID(F14,7,3))/4,0)*5))) -> 15
A15: 崇左城南二楼IDC机房 | B15: 16 | C15: =VLOOKUP(D15,'00设备表'!$D:$F,3,0) -> HW105-02 | D15: 政务外网区出口防火墙-2 | E15: =VLOOKUP(D15,'00设备表'!$D:$F,2,0) -> 华为1000E-F55 | F15: =VLOOKUP(G15,'00设备表'!$D:$F,3,0) -> HW105-05 | G15: 政务外网区专线交换机-2 | H15: =VLOOKUP(G15,'00设备表'!$D:$F,2,0) -> 华为CE6881H | I15: 多模双头尾纤 | J15: =IF(I15="多模双头尾纤","LC-LC"&" "&L15&"米",IF(I15="单模双头尾纤","SC-LC"&" "&L15&"米",IF(I15="MPO双头尾纤","MPO-MPO"&" "&L15&"米",IF(I15="以太网线","超五类线",0)))) -> LC-LC 15米 | K15: 2 | L15: =IF(C15=F15,10,(10+ROUNDUP(ABS(MID(C15,7,3)-MID(F15,7,3))/4,0)*5)) -> 15 | N15: =IF(L15=10,"架内走线","上走线") -> 上走线 | Q15: =IF(ABS(MID(C15,3,3)-MID(F15,3,3))<>0,"建议手动计算",IF(C15=F15,10,(10+ROUNDUP(ABS(MID(C15,7,3)-MID(F15,7,3))/4,0)*5))) -> 15
A16: 崇左城南二楼IDC机房 | B16: 18 | C16: =VLOOKUP(D16,'00设备表'!$D:$F,3,0) -> HW107-02 | D16: 互联网区出口防火墙-1 | E16: =VLOOKUP(D16,'00设备表'!$D:$F,2,0) -> 华为1000E-F55 | F16: =VLOOKUP(G16,'00设备表'!$D:$F,3,0) -> HW107-03 | G16: 互联网区出口防火墙-2 | H16: =VLOOKUP(G16,'00设备表'!$D:$F,2,0) -> 华为1000E-F55 | I16: 以太网线 | J16: =IF(I16="多模双头尾纤","LC-LC"&" "&L16&"米",IF(I16="单模双头尾纤","SC-LC"&" "&L16&"米",IF(I16="MPO双头尾纤","MPO-MPO"&" "&L16&"米",IF(I16="以太网线","超五类线",0)))) -> 超五类线 | K16: 2 | L16: =IF(C16=F16,10,(10+ROUNDUP(ABS(MID(C16,7,3)-MID(F16,7,3))/4,0)*5)) -> 15 | M16: =K16*L16 -> 30 | N16: =IF(L16=10,"架内走线","上走线") -> 上走线 | Q16: =IF(ABS(MID(C16,3,3)-MID(F16,3,3))<>0,"建议手动计算",IF(C16=F16,10,(10+ROUNDUP(ABS(MID(C16,7,3)-MID(F16,7,3))/4,0)*5))) -> 15
A17: 崇左城南二楼IDC机房 | B17: 19 | C17: =VLOOKUP(D17,'00设备表'!$D:$F,3,0) -> HW107-02 | D17: 互联网区出口防火墙-1 | E17: =VLOOKUP(D17,'00设备表'!$D:$F,2,0) -> 华为1000E-F55 | F17: =VLOOKUP(G17,'00设备表'!$D:$F,3,0) -> HW107-02 | G17: 互联网区出口交换机-1 | H17: =VLOOKUP(G17,'00设备表'!$D:$F,2,0) -> 华为CE6881H | I17: 多模双头尾纤 | J17: =IF(I17="多模双头尾纤","LC-LC"&" "&L17&"米",IF(I17="单模双头尾纤","SC-LC"&" "&L17&"米",IF(I17="MPO双头尾纤","MPO-MPO"&" "&L17&"米",IF(I17="以太网线","超五类线",0)))) -> LC-LC 10米 | K17: 2 | L17: =IF(C17=F17,10,(10+ROUNDUP(ABS(MID(C17,7,3)-MID(F17,7,3))/4,0)*5)) -> 10 | N17: =IF(L17=10,"架内走线","上走线") -> 架内走线 | Q17: =IF(ABS(MID(C17,3,3)-MID(F17,3,3))<>0,"建议手动计算",IF(C17=F17,10,(10+ROUNDUP(ABS(MID(C17,7,3)-MID(F17,7,3))/4,0)*5))) -> 10
A18: 崇左城南二楼IDC机房 | B18: 20 | C18: =VLOOKUP(D18,'00设备表'!$D:$F,3,0) -> HW107-02 | D18: 互联网区出口防火墙-1 | E18: =VLOOKUP(D18,'00设备表'!$D:$F,2,0) -> 华为1000E-F55 | F18: =VLOOKUP(G18,'00设备表'!$D:$F,3,0) -> HW107-03 | G18: 互联网区出口交换机-2 | H18: =VLOOKUP(G18,'00设备表'!$D:$F,2,0) -> 华为CE6881H | I18: 多模双头尾纤 | J18: =IF(I18="多模双头尾纤","LC-LC"&" "&L18&"米",IF(I18="单模双头尾纤","SC-LC"&" "&L18&"米",IF(I18="MPO双头尾纤","MPO-MPO"&" "&L18&"米",IF(I18="以太网线","超五类线",0)))) -> LC-LC 15米 | K18: 2 | L18: =IF(C18=F18,10,(10+ROUNDUP(ABS(MID(C18,7,3)-MID(F18,7,3))/4,0)*5)) -> 15 | N18: =IF(L18=10,"架内走线","上走线") -> 上走线 | P18: 至多云汇聚路由器 | Q18: =IF(ABS(MID(C18,3,3)-MID(F18,3,3))<>0,"建议手动计算",IF(C18=F18,10,(10+ROUNDUP(ABS(MID(C18,7,3)-MID(F18,7,3))/4,0)*5))) -> 15
A19: 崇左城南二楼IDC机房 | B19: 21 | C19: =VLOOKUP(D19,'00设备表'!$D:$F,3,0) -> HW107-02 | D19: 互联网区分光器-1 | E19: =VLOOKUP(D19,'00设备表'!$D:$F,2,0) -> 华为OOSSMRC00 | F19: HW109-01 | G19: ODF（163 MSE NE40) | H19: NE40 | I19: 单模双头尾纤 | J19: SC-LC 35米 | K19: 2 | L19: =IF(C19=F19,10,(10+ROUNDUP(ABS(MID(C19,7,3)-MID(F19,7,3))/4,0)*5)) -> 15 | N19: =IF(L19=10,"架内走线","上走线") -> 上走线 | Q19: =IF(ABS(MID(C19,3,3)-MID(F19,3,3))<>0,"建议手动计算",IF(C19=F19,10,(10+ROUNDUP(ABS(MID(C19,7,3)-MID(F19,7,3))/4,0)*5))) -> 建议手动计算
A20: 崇左城南二楼IDC机房 | B20: 22 | C20: =VLOOKUP(D20,'00设备表'!$D:$F,3,0) -> HW107-02 | D20: 互联网区出口防火墙-1 | E20: =VLOOKUP(D20,'00设备表'!$D:$F,2,0) -> 华为1000E-F55 | F20: =VLOOKUP(G20,'00设备表'!$D:$F,3,0) -> HW107-07 | G20: 互联网区专线交换机-1 | H20: =VLOOKUP(G20,'00设备表'!$D:$F,2,0) -> 华为CE6881H | I20: 多模双头尾纤 | J20: =IF(I20="多模双头尾纤","LC-LC"&" "&L20&"米",IF(I20="单模双头尾纤","SC-LC"&" "&L20&"米",IF(I20="MPO双头尾纤","MPO-MPO"&" "&L20&"米",IF(I20="以太网线","超五类线",0)))) -> LC-LC 20米 | K20: 2 | L20: =IF(C20=F20,10,(10+ROUNDUP(ABS(MID(C20,7,3)-MID(F20,7,3))/4,0)*5)) -> 20 | N20: =IF(L20=10,"架内走线","上走线") -> 上走线 | Q20: =IF(ABS(MID(C20,3,3)-MID(F20,3,3))<>0,"建议手动计算",IF(C20=F20,10,(10+ROUNDUP(ABS(MID(C20,7,3)-MID(F20,7,3))/4,0)*5))) -> 20
A21: 崇左城南二楼IDC机房 | B21: 22 | C21: =VLOOKUP(D21,'00设备表'!$D:$F,3,0) -> HW107-02 | D21: 互联网区出口防火墙-1 | E21: =VLOOKUP(D21,'00设备表'!$D:$F,2,0) -> 华为1000E-F55 | F21: =VLOOKUP(G21,'00设备表'!$D:$F,3,0) -> HW107-08 | G21: 互联网区专线交换机-2 | H21: =VLOOKUP(G21,'00设备表'!$D:$F,2,0) -> 华为CE6881H | I21: 多模双头尾纤 | J21: =IF(I21="多模双头尾纤","LC-LC"&" "&L21&"米",IF(I21="单模双头尾纤","SC-LC"&" "&L21&"米",IF(I21="MPO双头尾纤","MPO-MPO"&" "&L21&"米",IF(I21="以太网线","超五类线",0)))) -> LC-LC 20米 | K21: 2 | L21: =IF(C21=F21,10,(10+ROUNDUP(ABS(MID(C21,7,3)-MID(F21,7,3))/4,0)*5)) -> 20 | N21: =IF(L21=10,"架内走线","上走线") -> 上走线 | Q21: =IF(ABS(MID(C21,3,3)-MID(F21,3,3))<>0,"建议手动计算",IF(C21=F21,10,(10+ROUNDUP(ABS(MID(C21,7,3)-MID(F21,7,3))/4,0)*5))) -> 20
A22: 崇左城南二楼IDC机房 | B22: 23 | C22: =VLOOKUP(D22,'00设备表'!$D:$F,3,0) -> HW107-02 | D22: 互联网区出口防火墙-1 | E22: =VLOOKUP(D22,'00设备表'!$D:$F,2,0) -> 华为1000E-F55 | F22: =VLOOKUP(G22,'00设备表'!$D:$F,3,0) -> HW109-01 | G22: ODF（柳东方向） | H22: =VLOOKUP(G22,'00设备表'!$D:$F,2,0) -> ODF | I22: 单模双头尾纤 | J22: SC-LC 35米 | K22: 2 | L22: 35 | N22: =IF(L22=10,"架内走线","上走线") -> 上走线 | Q22: =IF(ABS(MID(C22,3,3)-MID(F22,3,3))<>0,"建议手动计算",IF(C22=F22,10,(10+ROUNDUP(ABS(MID(C22,7,3)-MID(F22,7,3))/4,0)*5))) -> 建议手动计算
A23: 崇左城南二楼IDC机房 | B23: 25 | C23: =VLOOKUP(D23,'00设备表'!$D:$F,3,0) -> HW107-03 | D23: 互联网区出口防火墙-2 | E23: =VLOOKUP(D23,'00设备表'!$D:$F,2,0) -> 华为1000E-F55 | F23: =VLOOKUP(G23,'00设备表'!$D:$F,3,0) -> HW107-02 | G23: 互联网区出口交换机-1 | H23: =VLOOKUP(G23,'00设备表'!$D:$F,2,0) -> 华为CE6881H | I23: 多模双头尾纤 | J23: =IF(I23="多模双头尾纤","LC-LC"&" "&L23&"米",IF(I23="单模双头尾纤","SC-LC"&" "&L23&"米",IF(I23="MPO双头尾纤","MPO-MPO"&" "&L23&"米",IF(I23="以太网线","超五类线",0)))) -> LC-LC 15米 | K23: 2 | L23: =IF(C23=F23,10,(10+ROUNDUP(ABS(MID(C23,7,3)-MID(F23,7,3))/4,0)*5)) -> 15 | N23: =IF(L23=10,"架内走线","上走线") -> 上走线 | Q23: =IF(ABS(MID(C23,3,3)-MID(F23,3,3))<>0,"建议手动计算",IF(C23=F23,10,(10+ROUNDUP(ABS(MID(C23,7,3)-MID(F23,7,3))/4,0)*5))) -> 15
A24: 崇左城南二楼IDC机房 | B24: 26 | C24: =VLOOKUP(D24,'00设备表'!$D:$F,3,0) -> HW107-03 | D24: 互联网区出口防火墙-2 | E24: =VLOOKUP(D24,'00设备表'!$D:$F,2,0) -> 华为1000E-F55 | F24: =VLOOKUP(G24,'00设备表'!$D:$F,3,0) -> HW107-03 | G24: 互联网区出口交换机-2 | H24: =VLOOKUP(G24,'00设备表'!$D:$F,2,0) -> 华为CE6881H | I24: 多模双头尾纤 | J24: =IF(I24="多模双头尾纤","LC-LC"&" "&L24&"米",IF(I24="单模双头尾纤","SC-LC"&" "&L24&"米",IF(I24="MPO双头尾纤","MPO-MPO"&" "&L24&"米",IF(I24="以太网线","超五类线",0)))) -> LC-LC 10米 | K24: 2 | L24: =IF(C24=F24,10,(10+ROUNDUP(ABS(MID(C24,7,3)-MID(F24,7,3))/4,0)*5)) -> 10 | N24: =IF(L24=10,"架内走线","上走线") -> 架内走线 | Q24: =IF(ABS(MID(C24,3,3)-MID(F24,3,3))<>0,"建议手动计算",IF(C24=F24,10,(10+ROUNDUP(ABS(MID(C24,7,3)-MID(F24,7,3))/4,0)*5))) -> 10
A25: 崇左城南二楼IDC机房 | B25: 27 | C25: =VLOOKUP(D25,'00设备表'!$D:$F,3,0) -> HW107-03 | D25: 互联网区出口防火墙-2 | E25: =VLOOKUP(D25,'00设备表'!$D:$F,2,0) -> 华为1000E-F55 | F25: =VLOOKUP(G25,'00设备表'!$D:$F,3,0) -> HW107-07 | G25: 互联网区专线交换机-1 | H25: =VLOOKUP(G25,'00设备表'!$D:$F,2,0) -> 华为CE6881H | I25: 多模双头尾纤 | J25: =IF(I25="多模双头尾纤","LC-LC"&" "&L25&"米",IF(I25="单模双头尾纤","SC-LC"&" "&L25&"米",IF(I25="MPO双头尾纤","MPO-MPO"&" "&L25&"米",IF(I25="以太网线","超五类线",0)))) -> LC-LC 15米 | K25: 2 | L25: =IF(C25=F25,10,(10+ROUNDUP(ABS(MID(C25,7,3)-MID(F25,7,3))/4,0)*5)) -> 15 | N25: =IF(L25=10,"架内走线","上走线") -> 上走线 | Q25: =IF(ABS(MID(C25,3,3)-MID(F25,3,3))<>0,"建议手动计算",IF(C25=F25,10,(10+ROUNDUP(ABS(MID(C25,7,3)-MID(F25,7,3))/4,0)*5))) -> 15
A26: 崇左城南二楼IDC机房 | B26: 27 | C26: =VLOOKUP(D26,'00设备表'!$D:$F,3,0) -> HW107-03 | D26: 互联网区出口防火墙-2 | E26: =VLOOKUP(D26,'00设备表'!$D:$F,2,0) -> 华为1000E-F55 | F26: =VLOOKUP(G26,'00设备表'!$D:$F,3,0) -> HW107-08 | G26: 互联网区专线交换机-2 | H26: =VLOOKUP(G26,'00设备表'!$D:$F,2,0) -> 华为CE6881H | I26: 多模双头尾纤 | J26: =IF(I26="多模双头尾纤","LC-LC"&" "&L26&"米",IF(I26="单模双头尾纤","SC-LC"&" "&L26&"米",IF(I26="MPO双头尾纤","MPO-MPO"&" "&L26&"米",IF(I26="以太网线","超五类线",0)))) -> LC-LC 20米 | K26: 2 | L26: =IF(C26=F26,10,(10+ROUNDUP(ABS(MID(C26,7,3)-MID(F26,7,3))/4,0)*5)) -> 20 | N26: =IF(L26=10,"架内走线","上走线") -> 上走线 | Q26: =IF(ABS(MID(C26,3,3)-MID(F26,3,3))<>0,"建议手动计算",IF(C26=F26,10,(10+ROUNDUP(ABS(MID(C26,7,3)-MID(F26,7,3))/4,0)*5))) -> 20
A27: 崇左城南二楼IDC机房 | B27: 27 | C27: =VLOOKUP(D27,'00设备表'!$D:$F,3,0) -> HW107-03 | D27: 互联网区分光器-2 | E27: =VLOOKUP(D27,'00设备表'!$D:$F,2,0) -> 华为OOSSMRC00 | F27: HW109-01 | G27: ODF（163 M6000-18S) | H27: M6000-18S | I27: 单模双头尾纤 | J27: SC-LC 35米 | K27: 2 | L27: =IF(C27=F27,10,(10+ROUNDUP(ABS(MID(C27,7,3)-MID(F27,7,3))/4,0)*5)) -> 15 | N27: =IF(L27=10,"架内走线","上走线") -> 上走线 | Q27: =IF(ABS(MID(C27,3,3)-MID(F27,3,3))<>0,"建议手动计算",IF(C27=F27,10,(10+ROUNDUP(ABS(MID(C27,7,3)-MID(F27,7,3))/4,0)*5))) -> 建议手动计算
A28: 崇左城南二楼IDC机房 | B28: 28 | C28: =VLOOKUP(D28,'00设备表'!$D:$F,3,0) -> HW108-07 | D28: 管理区防火墙-1 | E28: =VLOOKUP(D28,'00设备表'!$D:$F,2,0) -> 华为1000E-F125 | F28: =VLOOKUP(G28,'00设备表'!$D:$F,3,0) -> HW108-09 | G28: 管理区防火墙-2 | H28: =VLOOKUP(G28,'00设备表'!$D:$F,2,0) -> 华为1000E-F125 | I28: MPO双头尾纤 | J28: =IF(I28="多模双头尾纤","LC-LC"&" "&L28&"米",IF(I28="单模双头尾纤","SC-LC"&" "&L28&"米",IF(I28="MPO双头尾纤","MPO-MPO"&" "&L28&"米",IF(I28="以太网线","超五类线",0)))) -> MPO-MPO 15米 | K28: 2 | L28: =IF(C28=F28,10,(10+ROUNDUP(ABS(MID(C28,7,3)-MID(F28,7,3))/4,0)*5)) -> 15 | M28: =K28*L28 -> 30 | N28: =IF(L28=10,"架内走线","上走线") -> 上走线 | Q28: =IF(ABS(MID(C28,3,3)-MID(F28,3,3))<>0,"建议手动计算",IF(C28=F28,10,(10+ROUNDUP(ABS(MID(C28,7,3)-MID(F28,7,3))/4,0)*5))) -> 15
A29: 崇左城南二楼IDC机房 | B29: 29 | C29: =VLOOKUP(D29,'00设备表'!$D:$F,3,0) -> HW108-07 | D29: 管理区防火墙-1 | E29: =VLOOKUP(D29,'00设备表'!$D:$F,2,0) -> 华为1000E-F125 | F29: =VLOOKUP(G29,'00设备表'!$D:$F,3,0) -> HW108-07 | G29: 运维区万兆管理交换机-1 | H29: =VLOOKUP(G29,'00设备表'!$D:$F,2,0) -> 华为CE6881H | I29: 多模双头尾纤 | J29: =IF(I29="多模双头尾纤","LC-LC"&" "&L29&"米",IF(I29="单模双头尾纤","SC-LC"&" "&L29&"米",IF(I29="MPO双头尾纤","MPO-MPO"&" "&L29&"米",IF(I29="以太网线","超五类线",0)))) -> LC-LC 10米 | K29: 2 | L29: =IF(C29=F29,10,(10+ROUNDUP(ABS(MID(C29,7,3)-MID(F29,7,3))/4,0)*5)) -> 10 | N29: =IF(L29=10,"架内走线","上走线") -> 架内走线 | Q29: =IF(ABS(MID(C29,3,3)-MID(F29,3,3))<>0,"建议手动计算",IF(C29=F29,10,(10+ROUNDUP(ABS(MID(C29,7,3)-MID(F29,7,3))/4,0)*5))) -> 10
A30: 崇左城南二楼IDC机房 | B30: 30 | C30: =VLOOKUP(D30,'00设备表'!$D:$F,3,0) -> HW108-09 | D30: 管理区防火墙-2 | E30: =VLOOKUP(D30,'00设备表'!$D:$F,2,0) -> 华为1000E-F125 | F30: =VLOOKUP(G30,'00设备表'!$D:$F,3,0) -> HW108-09 | G30: 运维区万兆管理交换机-2 | H30: =VLOOKUP(G30,'00设备表'!$D:$F,2,0) -> 华为CE6881H | I30: 多模双头尾纤 | J30: =IF(I30="多模双头尾纤","LC-LC"&" "&L30&"米",IF(I30="单模双头尾纤","SC-LC"&" "&L30&"米",IF(I30="MPO双头尾纤","MPO-MPO"&" "&L30&"米",IF(I30="以太网线","超五类线",0)))) -> LC-LC 10米 | K30: 2 | L30: =IF(C30=F30,10,(10+ROUNDUP(ABS(MID(C30,7,3)-MID(F30,7,3))/4,0)*5)) -> 10 | M30: =K30*L30 -> 20 | N30: =IF(L30=10,"架内走线","上走线") -> 架内走线 | Q30: =IF(ABS(MID(C30,3,3)-MID(F30,3,3))<>0,"建议手动计算",IF(C30=F30,10,(10+ROUNDUP(ABS(MID(C30,7,3)-MID(F30,7,3))/4,0)*5))) -> 10
A31: 崇左城南二楼IDC机房 | B31: 31 | C31: =VLOOKUP(D31,'00设备表'!$D:$F,3,0) -> HW105-01 | D31: 政务外网区核心交换机-1 | E31: =VLOOKUP(D31,'00设备表'!$D:$F,2,0) -> 华为CE8865-4C | F31: =VLOOKUP(G31,'00设备表'!$D:$F,3,0) -> HW105-02 | G31: 政务外网区核心交换机-2 | H31: =VLOOKUP(G31,'00设备表'!$D:$F,2,0) -> 华为CE8865-4C | I31: 多模双头尾纤 | J31: =IF(I31="多模双头尾纤","LC-LC"&" "&L31&"米",IF(I31="单模双头尾纤","SC-LC"&" "&L31&"米",IF(I31="MPO双头尾纤","MPO-MPO"&" "&L31&"米",IF(I31="以太网线","超五类线",0)))) -> LC-LC 15米 | K31: 4 | L31: =IF(C31=F31,10,(10+ROUNDUP(ABS(MID(C31,7,3)-MID(F31,7,3))/4,0)*5)) -> 15 | N31: =IF(L31=10,"架内走线","上走线") -> 上走线 | Q31: =IF(ABS(MID(C31,3,3)-MID(F31,3,3))<>0,"建议手动计算",IF(C31=F31,10,(10+ROUNDUP(ABS(MID(C31,7,3)-MID(F31,7,3))/4,0)*5))) -> 15
A32: 崇左城南二楼IDC机房 | B32: 32 | C32: =VLOOKUP(D32,'00设备表'!$D:$F,3,0) -> HW105-01 | D32: 政务外网区核心交换机-1 | E32: =VLOOKUP(D32,'00设备表'!$D:$F,2,0) -> 华为CE8865-4C | F32: =VLOOKUP(G32,'00设备表'!$D:$F,3,0) -> HW105-02 | G32: 政务外网区核心交换机-2 | H32: =VLOOKUP(G32,'00设备表'!$D:$F,2,0) -> 华为CE8865-4C | I32: MPO双头尾纤 | J32: =IF(I32="多模双头尾纤","LC-LC"&" "&L32&"米",IF(I32="单模双头尾纤","SC-LC"&" "&L32&"米",IF(I32="MPO双头尾纤","MPO-MPO"&" "&L32&"米",IF(I32="以太网线","超五类线",0)))) -> MPO-MPO 15米 | K32: 2 | L32: =IF(C32=F32,10,(10+ROUNDUP(ABS(MID(C32,7,3)-MID(F32,7,3))/4,0)*5)) -> 15 | N32: =IF(L32=10,"架内走线","上走线") -> 上走线 | Q32: =IF(ABS(MID(C32,3,3)-MID(F32,3,3))<>0,"建议手动计算",IF(C32=F32,10,(10+ROUNDUP(ABS(MID(C32,7,3)-MID(F32,7,3))/4,0)*5))) -> 15
A33: 崇左城南二楼IDC机房 | B33: 33 | C33: =VLOOKUP(D33,'00设备表'!$D:$F,3,0) -> HW105-01 | D33: 政务外网区核心交换机-1 | E33: =VLOOKUP(D33,'00设备表'!$D:$F,2,0) -> 华为CE8865-4C | F33: =VLOOKUP(G33,'00设备表'!$D:$F,3,0) -> HW105-06 | G33: 政务外网区万兆业务交换机-1 | H33: =VLOOKUP(G33,'00设备表'!$D:$F,2,0) -> 华为CE6881H | I33: MPO双头尾纤 | J33: =IF(I33="多模双头尾纤","LC-LC"&" "&L33&"米",IF(I33="单模双头尾纤","SC-LC"&" "&L33&"米",IF(I33="MPO双头尾纤","MPO-MPO"&" "&L33&"米",IF(I33="以太网线","超五类线",0)))) -> MPO-MPO 20米 | K33: 1 | L33: =IF(C33=F33,10,(10+ROUNDUP(ABS(MID(C33,7,3)-MID(F33,7,3))/4,0)*5)) -> 20 | N33: =IF(L33=10,"架内走线","上走线") -> 上走线 | Q33: =IF(ABS(MID(C33,3,3)-MID(F33,3,3))<>0,"建议手动计算",IF(C33=F33,10,(10+ROUNDUP(ABS(MID(C33,7,3)-MID(F33,7,3))/4,0)*5))) -> 20
A34: 崇左城南二楼IDC机房 | B34: 34 | C34: =VLOOKUP(D34,'00设备表'!$D:$F,3,0) -> HW105-01 | D34: 政务外网区核心交换机-1 | E34: =VLOOKUP(D34,'00设备表'!$D:$F,2,0) -> 华为CE8865-4C | F34: =VLOOKUP(G34,'00设备表'!$D:$F,3,0) -> HW105-08 | G34: 政务外网区万兆业务交换机-2 | H34: =VLOOKUP(G34,'00设备表'!$D:$F,2,0) -> 华为CE6881H | I34: MPO双头尾纤 | J34: =IF(I34="多模双头尾纤","LC-LC"&" "&L34&"米",IF(I34="单模双头尾纤","SC-LC"&" "&L34&"米",IF(I34="MPO双头尾纤","MPO-MPO"&" "&L34&"米",IF(I34="以太网线","超五类线",0)))) -> MPO-MPO 20米 | K34: 1 | L34: =IF(C34=F34,10,(10+ROUNDUP(ABS(MID(C34,7,3)-MID(F34,7,3))/4,0)*5)) -> 20 | N34: =IF(L34=10,"架内走线","上走线") -> 上走线 | Q34: =IF(ABS(MID(C34,3,3)-MID(F34,3,3))<>0,"建议手动计算",IF(C34=F34,10,(10+ROUNDUP(ABS(MID(C34,7,3)-MID(F34,7,3))/4,0)*5))) -> 20
A35: 崇左城南二楼IDC机房 | B35: 35 | C35: =VLOOKUP(D35,'00设备表'!$D:$F,3,0) -> HW105-01 | D35: 政务外网区核心交换机-1 | E35: =VLOOKUP(D35,'00设备表'!$D:$F,2,0) -> 华为CE8865-4C | F35: =VLOOKUP(G35,'00设备表'!$D:$F,3,0) -> HW106-04 | G35: 政务外网区万兆存储交换机-1 | H35: =VLOOKUP(G35,'00设备表'!$D:$F,2,0) -> 华为CE6881H | I35: MPO双头尾纤 | J35: =IF(I35="多模双头尾纤","LC-LC"&" "&L35&"米",IF(I35="单模双头尾纤","SC-LC"&" "&L35&"米",IF(I35="MPO双头尾纤","MPO-MPO"&" "&L35&"米",IF(I35="以太网线","超五类线",0)))) -> MPO-MPO 15米 | K35: 1 | L35: =IF(C35=F35,10,(10+ROUNDUP(ABS(MID(C35,7,3)-MID(F35,7,3))/4,0)*5)) -> 15 | N35: =IF(L35=10,"架内走线","上走线") -> 上走线 | Q35: =IF(ABS(MID(C35,3,3)-MID(F35,3,3))<>0,"建议手动计算",IF(C35=F35,10,(10+ROUNDUP(ABS(MID(C35,7,3)-MID(F35,7,3))/4,0)*5))) -> 建议手动计算
A36: 崇左城南二楼IDC机房 | B36: 36 | C36: =VLOOKUP(D36,'00设备表'!$D:$F,3,0) -> HW105-01 | D36: 政务外网区核心交换机-1 | E36: =VLOOKUP(D36,'00设备表'!$D:$F,2,0) -> 华为CE8865-4C | F36: =VLOOKUP(G36,'00设备表'!$D:$F,3,0) -> HW106-06 | G36: 政务外网区万兆存储交换机-2 | H36: =VLOOKUP(G36,'00设备表'!$D:$F,2,0) -> 华为CE6881H | I36: MPO双头尾纤 | J36: =IF(I36="多模双头尾纤","LC-LC"&" "&L36&"米",IF(I36="单模双头尾纤","SC-LC"&" "&L36&"米",IF(I36="MPO双头尾纤","MPO-MPO"&" "&L36&"米",IF(I36="以太网线","超五类线",0)))) -> MPO-MPO 20米 | K36: 1 | L36: =IF(C36=F36,10,(10+ROUNDUP(ABS(MID(C36,7,3)-MID(F36,7,3))/4,0)*5)) -> 20 | N36: =IF(L36=10,"架内走线","上走线") -> 上走线 | Q36: =IF(ABS(MID(C36,3,3)-MID(F36,3,3))<>0,"建议手动计算",IF(C36=F36,10,(10+ROUNDUP(ABS(MID(C36,7,3)-MID(F36,7,3))/4,0)*5))) -> 建议手动计算
A37: 崇左城南二楼IDC机房 | B37: 37 | C37: =VLOOKUP(D37,'00设备表'!$D:$F,3,0) -> HW105-01 | D37: 政务外网区核心交换机-1 | E37: =VLOOKUP(D37,'00设备表'!$D:$F,2,0) -> 华为CE8865-4C | F37: =VLOOKUP(G37,'00设备表'!$D:$F,3,0) -> HW106-02 | G37: 政务外网区裸金属交换机-1 | H37: =VLOOKUP(G37,'00设备表'!$D:$F,2,0) -> 华为CE6881H | I37: MPO双头尾纤 | J37: =IF(I37="多模双头尾纤","LC-LC"&" "&L37&"米",IF(I37="单模双头尾纤","SC-LC"&" "&L37&"米",IF(I37="MPO双头尾纤","MPO-MPO"&" "&L37&"米",IF(I37="以太网线","超五类线",0)))) -> MPO-MPO 15米 | K37: 1 | L37: =IF(C37=F37,10,(10+ROUNDUP(ABS(MID(C37,7,3)-MID(F37,7,3))/4,0)*5)) -> 15 | N37: =IF(L37=10,"架内走线","上走线") -> 上走线 | Q37: =IF(ABS(MID(C37,3,3)-MID(F37,3,3))<>0,"建议手动计算",IF(C37=F37,10,(10+ROUNDUP(ABS(MID(C37,7,3)-MID(F37,7,3))/4,0)*5))) -> 建议手动计算
A38: 崇左城南二楼IDC机房 | B38: 38 | C38: =VLOOKUP(D38,'00设备表'!$D:$F,3,0) -> HW105-01 | D38: 政务外网区核心交换机-1 | E38: =VLOOKUP(D38,'00设备表'!$D:$F,2,0) -> 华为CE8865-4C | F38: =VLOOKUP(G38,'00设备表'!$D:$F,3,0) -> HW106-03 | G38: 政务外网区裸金属交换机-2 | H38: =VLOOKUP(G38,'00设备表'!$D:$F,2,0) -> 华为CE6881H | I38: MPO双头尾纤 | J38: =IF(I38="多模双头尾纤","LC-LC"&" "&L38&"米",IF(I38="单模双头尾纤","SC-LC"&" "&L38&"米",IF(I38="MPO双头尾纤","MPO-MPO"&" "&L38&"米",IF(I38="以太网线","超五类线",0)))) -> MPO-MPO 15米 | K38: 1 | L38: =IF(C38=F38,10,(10+ROUNDUP(ABS(MID(C38,7,3)-MID(F38,7,3))/4,0)*5)) -> 15 | N38: =IF(L38=10,"架内走线","上走线") -> 上走线 | P38: 黄茅坪灾备防火墙 | Q38: =IF(ABS(MID(C38,3,3)-MID(F38,3,3))<>0,"建议手动计算",IF(C38=F38,10,(10+ROUNDUP(ABS(MID(C38,7,3)-MID(F38,7,3))/4,0)*5))) -> 建议手动计算
A39: 崇左城南二楼IDC机房 | B39: 39 | C39: =VLOOKUP(D39,'00设备表'!$D:$F,3,0) -> HW105-01 | D39: 政务外网区核心交换机-1 | E39: =VLOOKUP(D39,'00设备表'!$D:$F,2,0) -> 华为CE8865-4C | F39: =VLOOKUP(G39,'00设备表'!$D:$F,3,0) -> HW105-01 | G39: 政务外网区安全交换机-1 | H39: =VLOOKUP(G39,'00设备表'!$D:$F,2,0) -> 华为CE6881H | I39: MPO双头尾纤 | J39: =IF(I39="多模双头尾纤","LC-LC"&" "&L39&"米",IF(I39="单模双头尾纤","SC-LC"&" "&L39&"米",IF(I39="MPO双头尾纤","MPO-MPO"&" "&L39&"米",IF(I39="以太网线","超五类线",0)))) -> MPO-MPO 10米 | K39: 1 | L39: =IF(C39=F39,10,(10+ROUNDUP(ABS(MID(C39,7,3)-MID(F39,7,3))/4,0)*5)) -> 10 | N39: =IF(L39=10,"架内走线","上走线") -> 架内走线 | Q39: =IF(ABS(MID(C39,3,3)-MID(F39,3,3))<>0,"建议手动计算",IF(C39=F39,10,(10+ROUNDUP(ABS(MID(C39,7,3)-MID(F39,7,3))/4,0)*5))) -> 10
A40: 崇左城南二楼IDC机房 | B40: 40 | C40: =VLOOKUP(D40,'00设备表'!$D:$F,3,0) -> HW105-01 | D40: 政务外网区核心交换机-1 | E40: =VLOOKUP(D40,'00设备表'!$D:$F,2,0) -> 华为CE8865-4C | F40: =VLOOKUP(G40,'00设备表'!$D:$F,3,0) -> HW105-02 | G40: 政务外网区安全交换机-2 | H40: =VLOOKUP(G40,'00设备表'!$D:$F,2,0) -> 华为CE6881H | I40: MPO双头尾纤 | J40: =IF(I40="多模双头尾纤","LC-LC"&" "&L40&"米",IF(I40="单模双头尾纤","SC-LC"&" "&L40&"米",IF(I40="MPO双头尾纤","MPO-MPO"&" "&L40&"米",IF(I40="以太网线","超五类线",0)))) -> MPO-MPO 15米 | K40: 1 | L40: =IF(C40=F40,10,(10+ROUNDUP(ABS(MID(C40,7,3)-MID(F40,7,3))/4,0)*5)) -> 15 | N40: =IF(L40=10,"架内走线","上走线") -> 上走线 | Q40: =IF(ABS(MID(C40,3,3)-MID(F40,3,3))<>0,"建议手动计算",IF(C40=F40,10,(10+ROUNDUP(ABS(MID(C40,7,3)-MID(F40,7,3))/4,0)*5))) -> 15
...

Sheet 材料表
A1: 序号 | B1: 名称 | C1: 型号 | D1: 单位 | E1: 崇左城南二楼IDC机房 | F1: 柳东数据中心东202机房 | G1: 合计 | H1: 单价（不含税价） | I1: 合价
A3: 1 | B3: 水晶头 | D3: 个 | E3: =75*2 -> 150 | G3: =SUM(E3:F3) -> 150 | H3: 1.3 | I3: =H3*G3 -> 195
A4: 2 | B4: 以太网线 | C4: 超五类线 | D4: 米 | E4: =SUMIFS(布线计划表!M:M,布线计划表!I:I,B4,布线计划表!J:J,C4,布线计划表!A:A,$E$1) -> 2385 | F4: =SUMIFS(布线计划表!M:M,布线计划表!I:I,B4,布线计划表!J:J,C4,布线计划表!A:A,$F$1) -> 20 | G4: =SUM(E4:F4) -> 2405 | H4: 1.5 | I4: =H4*G4 -> 3607.5
A5: 3 | B5: 单模双头尾纤 | C5: FC-FC 1米 | D5: 条 | E5: =SUMIFS(布线计划表!K:K,布线计划表!I:I,B5,布线计划表!J:J,C5,布线计划表!A:A,$E$1) -> 0 | F5: =SUMIFS(布线计划表!K:K,布线计划表!I:I,B5,布线计划表!J:J,C5,布线计划表!A:A,$F$1) -> 0 | G5: =SUM(E5:F5) -> 0 | H5: 8 | I5: =H5*G5 -> 0
A6: 4 | B6: 单模双头尾纤 | C6: FC-FC 2米 | D6: 条 | E6: =SUMIFS(布线计划表!K:K,布线计划表!I:I,B6,布线计划表!J:J,C6,布线计划表!A:A,$E$1) -> 0 | F6: =SUMIFS(布线计划表!K:K,布线计划表!I:I,B6,布线计划表!J:J,C6,布线计划表!A:A,$F$1) -> 0 | G6: =SUM(E6:F6) -> 0 | H6: 8 | I6: =H6*G6 -> 0
A7: 5 | B7: 单模双头尾纤 | C7: FC-FC 3米 | D7: 条 | E7: =SUMIFS(布线计划表!K:K,布线计划表!I:I,B7,布线计划表!J:J,C7,布线计划表!A:A,$E$1) -> 0 | F7: =SUMIFS(布线计划表!K:K,布线计划表!I:I,B7,布线计划表!J:J,C7,布线计划表!A:A,$F$1) -> 0 | G7: =SUM(E7:F7) -> 0 | H7: 8 | I7: =H7*G7 -> 0
A8: 6 | B8: 单模双头尾纤 | C8: FC-FC 5米 | D8: 条 | E8: =SUMIFS(布线计划表!K:K,布线计划表!I:I,B8,布线计划表!J:J,C8,布线计划表!A:A,$E$1) -> 0 | F8: =SUMIFS(布线计划表!K:K,布线计划表!I:I,B8,布线计划表!J:J,C8,布线计划表!A:A,$F$1) -> 0 | G8: =SUM(E8:F8) -> 0 | H8: 8 | I8: =H8*G8 -> 0
A9: 7 | B9: 单模双头尾纤 | C9: FC-FC 7米 | D9: 条 | E9: =SUMIFS(布线计划表!K:K,布线计划表!I:I,B9,布线计划表!J:J,C9,布线计划表!A:A,$E$1) -> 0 | F9: =SUMIFS(布线计划表!K:K,布线计划表!I:I,B9,布线计划表!J:J,C9,布线计划表!A:A,$F$1) -> 0 | G9: =SUM(E9:F9) -> 0 | H9: 9 | I9: =H9*G9 -> 0
A10: 8 | B10: 单模双头尾纤 | C10: FC-FC 10米 | D10: 条 | E10: =SUMIFS(布线计划表!K:K,布线计划表!I:I,B10,布线计划表!J:J,C10,布线计划表!A:A,$E$1) -> 0 | F10: =SUMIFS(布线计划表!K:K,布线计划表!I:I,B10,布线计划表!J:J,C10,布线计划表!A:A,$F$1) -> 0 | G10: =SUM(E10:F10) -> 0 | H10: 10 | I10: =H10*G10 -> 0
A11: 9 | B11: 单模双头尾纤 | C11: FC-FC 15米 | D11: 条 | E11: =SUMIFS(布线计划表!K:K,布线计划表!I:I,B11,布线计划表!J:J,C11,布线计划表!A:A,$E$1) -> 0 | F11: =SUMIFS(布线计划表!K:K,布线计划表!I:I,B11,布线计划表!J:J,C11,布线计划表!A:A,$F$1) -> 0 | G11: =SUM(E11:F11) -> 0 | H11: 12 | I11: =H11*G11 -> 0
A12: 10 | B12: 单模双头尾纤 | C12: FC-FC 20米 | D12: 条 | E12: =SUMIFS(布线计划表!K:K,布线计划表!I:I,B12,布线计划表!J:J,C12,布线计划表!A:A,$E$1) -> 0 | F12: =SUMIFS(布线计划表!K:K,布线计划表!I:I,B12,布线计划表!J:J,C12,布线计划表!A:A,$F$1) -> 0 | G12: =SUM(E12:F12) -> 0 | H12: 14 | I12: =H12*G12 -> 0
A13: 11 | B13: 单模双头尾纤 | C13: FC-FC 25米 | D13: 条 | E13: =SUMIFS(布线计划表!K:K,布线计划表!I:I,B13,布线计划表!J:J,C13,布线计划表!A:A,$E$1) -> 0 | F13: =SUMIFS(布线计划表!K:K,布线计划表!I:I,B13,布线计划表!J:J,C13,布线计划表!A:A,$F$1) -> 0 | G13: =SUM(E13:F13) -> 0 | H13: 16 | I13: =H13*G13 -> 0
A14: 12 | B14: 单模双头尾纤 | C14: FC-FC 30米 | D14: 条 | E14: =SUMIFS(布线计划表!K:K,布线计划表!I:I,B14,布线计划表!J:J,C14,布线计划表!A:A,$E$1) -> 0 | F14: =SUMIFS(布线计划表!K:K,布线计划表!I:I,B14,布线计划表!J:J,C14,布线计划表!A:A,$F$1) -> 0 | G14: =SUM(E14:F14) -> 0 | H14: 18 | I14: =H14*G14 -> 0
A15: 13 | B15: 单模双头尾纤 | C15: FC-FC 35米 | D15: 条 | E15: =SUMIFS(布线计划表!K:K,布线计划表!I:I,B15,布线计划表!J:J,C15,布线计划表!A:A,$E$1) -> 0 | F15: =SUMIFS(布线计划表!K:K,布线计划表!I:I,B15,布线计划表!J:J,C15,布线计划表!A:A,$F$1) -> 0 | G15: =SUM(E15:F15) -> 0 | H15: 20 | I15: =H15*G15 -> 0
A16: 14 | B16: 单模双头尾纤 | C16: FC-FC 40米 | D16: 条 | E16: =SUMIFS(布线计划表!K:K,布线计划表!I:I,B16,布线计划表!J:J,C16,布线计划表!A:A,$E$1) -> 0 | F16: =SUMIFS(布线计划表!K:K,布线计划表!I:I,B16,布线计划表!J:J,C16,布线计划表!A:A,$F$1) -> 0 | G16: =SUM(E16:F16) -> 0 | H16: 22 | I16: =H16*G16 -> 0
... A166: 164 | B166: 多模双头尾纤 | C166: SC-SC 50米 | D166: 条 | E166: =SUMIFS(布线计划表!K:K,布线计划表!I:I,B166,布线计划表!J:J,C166,布线计划表!A:A,$E$1) -> 0 | F166: =SUMIFS(布线计划表!K:K,布线计划表!I:I,B166,布线计划表!J:J,C166,布线计划表!A:A,$F$1) -> 0 | G166: =SUM(E166:F166) -> 0 | H166: 43 | I166: =H166*G166 -> 0
A167: 165 | B167: MPO双头尾纤 | C167: MPO-MPO 5米 | D167: 条 | E167: =SUMIFS(布线计划表!K:K,布线计划表!I:I,B167,布线计划表!J:J,C167,布线计划表!A:A,$E$1) -> 0 | F167: =SUMIFS(布线计划表!K:K,布线计划表!I:I,B167,布线计划表!J:J,C167,布线计划表!A:A,$F$1) -> 0 | G167: =SUM(E167:F167) -> 0 | H167: 200 | I167: =H167*G167 -> 0 | J167: 40G多模MPO模块使用
A168: 166 | B168: MPO双头尾纤 | C168: MPO-MPO 10米 | D168: 条 | E168: =SUMIFS(布线计划表!K:K,布线计划表!I:I,B168,布线计划表!J:J,C168,布线计划表!A:A,$E$1) -> 13 | F168: =SUMIFS(布线计划表!K:K,布线计划表!I:I,B168,布线计划表!J:J,C168,布线计划表!A:A,$F$1) -> 0 | G168: =SUM(E168:F168) -> 13 | H168: 320 | I168: =H168*G168 -> 4160 | J168: 40G多模MPO模块使用
A169: 167 | B169: MPO双头尾纤 | C169: MPO-MPO 15米 | D169: 条 | E169: =SUMIFS(布线计划表!K:K,布线计划表!I:I,B169,布线计划表!J:J,C169,布线计划表!A:A,$E$1) -> 83 | F169: =SUMIFS(布线计划表!K:K,布线计划表!I:I,B169,布线计划表!J:J,C169,布线计划表!A:A,$F$1) -> 0 | G169: =SUM(E169:F169) -> 83 | H169: 395 | I169: =H169*G169 -> 32785 | J169: 40G多模MPO模块使用
A170: 168 | B170: MPO双头尾纤 | C170: MPO-MPO 20米 | D170: 条 | E170: =SUMIFS(布线计划表!K:K,布线计划表!I:I,B170,布线计划表!J:J,C170,布线计划表!A:A,$E$1) -> 12 | F170: =SUMIFS(布线计划表!K:K,布线计划表!I:I,B170,布线计划表!J:J,C170,布线计划表!A:A,$F$1) -> 0 | G170: =SUM(E170:F170) -> 12 | H170: 470 | I170: =H170*G170 -> 5640 | J170: 40G多模MPO模块使用
A171: 169 | B171: MPO双头尾纤 | C171: MPO-MPO 25米 | D171: 条 | E171: =SUMIFS(布线计划表!K:K,布线计划表!I:I,B171,布线计划表!J:J,C171,布线计划表!A:A,$E$1) -> 0 | F171: =SUMIFS(布线计划表!K:K,布线计划表!I:I,B171,布线计划表!J:J,C171,布线计划表!A:A,$F$1) -> 0 | G171: =SUM(E171:F171) -> 0 | H171: 545 | I171: =H171*G171 -> 0 | J171: 40G多模MPO模块使用
A172: 170 | B172: MPO双头尾纤 | C172: MPO-MPO 30米 | D172: 条 | E172: =SUMIFS(布线计划表!K:K,布线计划表!I:I,B172,布线计划表!J:J,C172,布线计划表!A:A,$E$1) -> 0 | F172: =SUMIFS(布线计划表!K:K,布线计划表!I:I,B172,布线计划表!J:J,C172,布线计划表!A:A,$F$1) -> 0 | G172: =SUM(E172:F172) -> 0 | H172: 620 | I172: =H172*G172 -> 0 | J172: 40G多模MPO模块使用
A173: 171 | B173: MPO双头尾纤 | C173: MPO-MPO 35米 | D173: 条 | E173: =SUMIFS(布线计划表!K:K,布线计划表!I:I,B173,布线计划表!J:J,C173,布线计划表!A:A,$E$1) -> 0 | F173: =SUMIFS(布线计划表!K:K,布线计划表!I:I,B173,布线计划表!J:J,C173,布线计划表!A:A,$F$1) -> 0 | G173: =SUM(E173:F173) -> 0 | I173: =H173*G173 -> 0 | J173: 40G多模MPO模块使用
A174: 172 | B174: MPO双头尾纤 | C174: MPO-MPO 40米 | D174: 条 | E174: =SUMIFS(布线计划表!K:K,布线计划表!I:I,B174,布线计划表!J:J,C174,布线计划表!A:A,$E$1) -> 0 | F174: =SUMIFS(布线计划表!K:K,布线计划表!I:I,B174,布线计划表!J:J,C174,布线计划表!A:A,$F$1) -> 0 | G174: =SUM(E174:F174) -> 0 | H174: 845 | I174: =H174*G174 -> 0 | J174: 40G多模MPO模块使用
A175: 173 | B175: MPO双头尾纤 | C175: MPO-MPO 45米 | D175: 条 | E175: =SUMIFS(布线计划表!K:K,布线计划表!I:I,B175,布线计划表!J:J,C175,布线计划表!A:A,$E$1) -> 0 | F175: =SUMIFS(布线计划表!K:K,布线计划表!I:I,B175,布线计划表!J:J,C175,布线计划表!A:A,$F$1) -> 0 | G175: =SUM(E175:F175) -> 0 | I175: =H175*G175 -> 0 | J175: 40G多模MPO模块使用
A176: 174 | B176: MPO双头尾纤 | C176: MPO-MPO 50米 | D176: 条 | E176: =SUMIFS(布线计划表!K:K,布线计划表!I:I,B176,布线计划表!J:J,C176,布线计划表!A:A,$E$1) -> 0 | F176: =SUMIFS(布线计划表!K:K,布线计划表!I:I,B176,布线计划表!J:J,C176,布线计划表!A:A,$F$1) -> 0 | G176: =SUM(E176:F176) -> 0 | H176: 1099 | I176: =H176*G176 -> 0 | J176: 40G多模MPO模块使用
A177: 110 | B177: 标签纸 | C177: P50-25-600（50mm*25mm，600片/卷，用作设备二维码标签） | D177: 卷 | E177: 1 | F177: 1 | G177: =SUM(E177:F177) -> 2 | H177: 100 | I177: =H177*G177 -> 200 | J177: 每1台设备用1张
A178: 111 | B178: 标签纸 | C178: QS-03F-150（35*45+50mm，150片/卷，用作机房内尾纤、网线及设备电源线标签） | D178: 卷 | E178: 30 | F178: 1 | G178: =SUM(E178:F178) -> 31 | H178: 100 | I178: =H178*G178 -> 3100 | J178: 每1根尾纤2张标签纸、 每1根网线2张标签纸、 每1根电源线4张标签纸（设备侧1张，电源盘3张）
A179: 112 | B179: 标签纸 | C179: QS-05F-150（35*45+35mm，150片/卷，用作出机房尾纤，可打印二维码） | D179: 卷 | E179: 1 | F179: 1 | G179: =SUM(E179:F179) -> 2 | H179: 100 | I179: =H179*G179 -> 200 | J179: 1条光路4张（ 本机房2张、远端机房2张 ）
A180: 113 | B180: 标签纸 | C180: CT35-150-100（标签尺寸35mm*150mm，100片/卷，用作新增机架,机架电源线） | D180: 卷 | E180: 1 | F180: 1 | G180: =SUM(E180:F180) -> 2 | H180: 150 | I180: =H180*G180 -> 300 | J180: 每1架2张（前后各1张）
A181: 114 | B181: 碳带 | C181: 重庆品胜RP50-5045（907）（产品尺寸50mm*45m，墨层特性树脂基，碳带颜色黑色） | D181: 卷 | E181: 17 | F181: 1 | G181: =SUM(E181:F181) -> 18 | H181: 200 | I181: =H181*G181 -> 3600 | J181: 以上标签每2盒消耗1盒碳带，标签纸损耗率按2%计算
A182: 115 | B182: 尾纤套管 | C182: 直径20mm | D182: 米 | E182: 30 | F182: 5 | G182: =SUM(E182:F182) -> 35 | H182: 1.5 | I182: =H182*G182 -> 52.5
A183: 116 | B183: 尾纤专用包带 | C183: 黄色，宽带4.5cm | D183: 米 | E183: 30 | F183: 5 | G183: =SUM(E183:F183) -> 35 | H183: 2.5 | I183: =H183*G183 -> 87.5
A184: 117 | B184: 线缆专用绑扎带 | C184: 黄色绒面、透明勾面，宽度1cm，薄型，25米/卷 | D184: 卷 | E184: 4 | F184: 1 | G184: =SUM(E184:F184) -> 5 | H184: 4 | I184: =H184*G184 -> 20
A185: 118 | B185: 尼龙扎带 | C185: 5×300 | D185: 袋 | E185: 6 | F185: 1 | G185: =SUM(E185:F185) -> 7 | H185: 45 | I185: =H185*G185 -> 315
A186: 119 | B186: 尼龙扎带 | C186: 5×800 | D186: 袋 | E186: 6 | F186: 1 | G186: =SUM(E186:F186) -> 7 | H186: 80 | I186: =H186*G186 -> 560
A187: 120 | B187: 10GE光模块 | C187: 多模光模块 | D187: 个 | G187: =SUM(E187:F187) -> 0 | H187: 2000 | I187: =H187*G187 -> 0
A188: 121 | B188: GE光模块 | C188: 多模光模块 | D188: 个 | E188: 16 | G188: =SUM(E188:F188) -> 16 | H188: 1000 | I188: =H188*G188 -> 16000
A189: 120 | B189: 10GE光模块 | C189: 单模光模块 | D189: 个 | E189: 6 | F189: 6 | G189: =SUM(E189:F189) -> 12 | H189: 2000 | I189: =H189*G189 -> 24000
A190: 121 | B190: 电模块 | C190: RJ45电模块（电口转光口） | D190: 个 | G190: =SUM(E190:F190) -> 0 | H190: 2000 | I190: =H190*G190 -> 0

Sheet 00设备表
A1: 序号 | B1: 所属区域 | C1: 设备类型 | D1: 设备名称 | E1: 设备型号 | F1: 所属机架编号
A2: 1 | C2: ODF | D2: ODF（柳东方向） | E2: ODF | F2: HW109-01
A3: 2 | B3: 政务外网区 | C3: 安全设备 | D3: 政务外网区出口防火墙-1 | E3: 华为1000E-F55 | F3: HW105-01
A4: 3 | B4: 政务外网区 | C4: 网络设备 | D4: 政务外网区安全交换机-1 | E4: 华为CE6881H | F4: HW105-01
A5: 3 | B5: 政务外网区 | C5: 网络设备 | D5: 政务外网区安全池交换机-1 | E5: 华为CE6881H | F5: HW105-01
A6: 4 | B6: 政务外网区 | C6: 服务器 | D6: 政务外网区安全节点-1 | E6: 烽火R220K V2 | F6: HW105-01
A7: 5 | B7: 政务外网区 | C7: 安全设备 | D7: 政务外网区流量探针-1 | E7: 绿盟UTSNX3-HHB | F7: HW105-01
A8: 6 | B8: 政务外网区 | C8: 服务器 | D8: 政务外网区租户安全-5 | E8: 中兴R5930 G2 | F8: HW105-01
A9: 7 | B9: 政务外网区 | C9: 服务器 | D9: 政务外网区租户安全-3 | E9: 中兴R5930 G2 | F9: HW105-01
A10: 8 | B10: 政务外网区 | C10: 服务器 | D10: 政务外网区租户安全-1 | E10: 中兴R5930 G2 | F10: HW105-01
A11: 9 | B11: 政务外网区 | C11: 网络设备 | D11: 政务外网区核心交换机-1 | E11: 华为CE8865-4C | F11: HW105-01
A12: 10 | B12: 政务外网区 | C12: 安全设备 | D12: 政务外网区出口防火墙-2 | E12: 华为1000E-F55 | F12: HW105-02
A13: 11 | B13: 政务外网区 | C13: 网络设备 | D13: 政务外网区安全交换机-2 | E13: 华为CE6881H | F13: HW105-02
A14: 12 | B14: 政务外网区 | C14: 网络设备 | D14: 政务外网区安全池交换机-2 | E14: 华为CE6881H | F14: HW105-02
... A58: 53 | B58: 政务外网区 | C58: 服务器 | D58: 政务外网区裸金属网关-1 | E58: 烽火R220K V2 | F58: HW106-02
B59: 政务外网区 | C59: 服务器 | D59: 政务外网区裸金属节点-1 | E59: 烽火G440K V2 | F59: HW106-02
A60: 54 | B60: 政务外网区 | C60: 网络设备 | D60: 政务外网区裸金属交换机-2 | E60: 华为CE6881H | F60: HW106-03
A61: 55 | B61: 政务外网区 | C61: 服务器 | D61: 政务外网区裸金属网关-2 | E61: 烽火R220K V2 | F61: HW106-03
A62: 56 | B62: 政务外网区 | C62: 服务器 | D62: 政务外网区裸金属节点-2 | E62: 烽火G440K V2 | F62: HW106-03
A63: 57 | B63: 政务外网区 | C63: 网络设备 | D63: 政务外网区万兆存储交换机-1 | E63: 华为CE6881H | F63: HW106-04
A64: 58 | B64: 政务外网区 | C64: 网络设备 | D64: 政务外网区千兆BMC交换机-3 | E64: 华为5855 | F64: HW106-04
A65: 59 | B65: 政务外网区 | C65: 存储设备 | D65: 政务外网区普通块存储-4 | E65: 华为9520 | F65: HW106-04
A66: 60 | B66: 政务外网区 | C66: 存储设备 | D66: 政务外网区普通块存储-3 | E66: 华为9520 | F66: HW106-04
A67: 61 | B67: 政务外网区 | C67: 存储设备 | D67: 政务外网区普通块存储-2 | E67: 华为9520 | F67: HW106-04
A68: 62 | B68: 政务外网区 | C68: 存储设备 | D68: 政务外网区普通块存储-1 | E68: 华为9520 | F68: HW106-04
A69: 63 | B69: 政务外网区 | C69: 网络设备 | D69: 政务外网区万兆存储交换机-2 | E69: 华为CE6881H | F69: HW106-06
A70: 64 | B70: 政务外网区 | C70: 服务器 | D70: 政务外网区本地备份节点-1 | E70: 中兴R5530 G2 | F70: HW106-06
A71: 65 | B71: 政务外网区 | C71: 存储设备 | D71: 政务外网区SSD块存储-1 | E71: 华为5500 | F71: HW106-06
... A149: 143 | B149: 管理网 | C149: 安全设备 | D149: 管理区防火墙-1 | E149: 华为1000E-F125 | F149: HW108-07
B150: 管理网 | C150: 安全设备 | D150: 管理区SSL VPN-1 | E150: 信安G1300 | F150: HW108-07
A151: 144 | B151: 管理网 | C151: 安全设备 | D151: 政务外网区密码机-1 | E151: 信安SJJ186 | F151: HW108-07
A152: 145 | B152: 管理网 | C152: 安全设备 | D152: 政务外网区密码机-2 | E152: 信安SJJ186 | F152: HW108-07
A153: 147 | B153: 管理网 | C153: 服务器 | D153: 运维区态势感知-3 | E153: 中兴R5930 G2 | F153: HW108-07
A154: 148 | B154: 管理网 | C154: 服务器 | D154: 运维区态势感知-1 | E154: 中兴R5930 G2 | F154: HW108-07
A155: 149 | B155: 管理网 | C155: 网络设备 | D155: 管理区核心交换机-1 | E155: 华为CE16804 | F155: HW108-07
B156: 管理网 | C156: 安全设备 | D156: 网闸-1 | E156: 天融信TopRules(FT-A10) | F156: HW108-07
B157: 互联网区 | C157: 安全设备 | D157: 互联网区流量探针-1 | E157: 天融信TopAPT3000 | F157: HW108-07
A158: 150 | B158: 管理区 | C158: 网络设备 | D158: 运维区万兆管理交换机-2 | E158: 华为CE6881H | F158: HW108-09
A159: 151 | B159: 管理网 | C159: 安全设备 | D159: 管理区防火墙-2 | E159: 华为1000E-F125 | F159: HW108-09
A160: 152 | B160: 管理网 | C160: 安全设备 | D160: 管理区SSL VPN-2 | E160: 信安G1300 | F160: HW108-09
...

Sheet 01核心交换机(6台)
